<html><body><h2>File (last 1,000 lines): /var/log/httpd/error_log</h2><h5>Page last updated on: 2014-08-23 17:21:00 UTC<br>Page last updated on: 2014-08-23 10:21:00 PST</h5><table><tr><td bgcolor=#CCCCCC><b>Critical(s):</b></td><td bgcolor=#FF0000><b>0</b></td></tr><tr><td bgcolor=#CCCCCC><b>Error(s):</b></td><td bgcolor=#FF0000><b>1060</b></td></tr><tr><td bgcolor=#CCCCCC><b>Fatal(s):</b></td><td bgcolor=#FF0000><b>0</b></td></tr><tr><td bgcolor=#CCCCCC><b>Serialize(s):</b></td><td bgcolor=#FFFF00><b>0</b></td></tr><tr><td bgcolor=#CCCCCC><b>Warning(s):</b></td><td bgcolor=#FFFF00><b>0</b></td></tr></table><br>[Thu Aug 21 22:03:24 2014] [error] ('production.hcc', 1408683804, {'sys_module': 'base', 'source': 'django.request', 'host': '72.46.140.186', 'session': None, 'user': u'', 'time': '1408709004629', 'datestamp': '2014-08-22T05:03:24.629959', 'level': 'ERROR', 'sys_host': 'ip-10-172-93-72', 'msecs': 629.364013671875})<br>[Thu Aug 21 22:03:24 2014] [error] [client 198.63.231.28] mod_wsgi (pid=1758): Exception occurred processing WSGI script '/usr/lib/apx-hcc/hcc_project/hcc_project/wsgi.py'.<br>[Thu Aug 21 22:03:24 2014] [error] [client 198.63.231.28] Traceback (most recent call last):<br>[Thu Aug 21 22:03:24 2014] [error] [client 198.63.231.28]   File "/usr/lib/apx-hcc/.venv/lib/python2.7/site-packages/django/core/handlers/wsgi.py", line 255, in __call__<br>[Thu Aug 21 22:03:24 2014] [error] [client 198.63.231.28]     response = self.get_response(request)<br>[Thu Aug 21 22:03:24 2014] [error] [client 198.63.231.28]   File "/usr/lib/apx-hcc/.venv/lib/python2.7/site-packages/django/core/handlers/base.py", line 178, in get_response<br>[Thu Aug 21 22:03:24 2014] [error] [client 198.63.231.28]     response = self.handle_uncaught_exception(request, resolver, sys.exc_info())<br>[Thu Aug 21 22:03:24 2014] [error] [client 198.63.231.28]   File "/usr/lib/apx-hcc/.venv/lib/python2.7/site-packages/django/core/handlers/base.py", line 212, in handle_uncaught_exception<br>[Thu Aug 21 22:03:24 2014] [error] [client 198.63.231.28]     'request': request<br>[Thu Aug 21 22:03:24 2014] [error] [client 198.63.231.28]   File "/usr/lib64/python2.7/logging/__init__.py", line 1166, in error<br>[Thu Aug 21 22:03:24 2014] [error] [client 198.63.231.28]     self._log(ERROR, msg, args, **kwargs)<br>[Thu Aug 21 22:03:24 2014] [error] [client 198.63.231.28]   File "/usr/lib64/python2.7/logging/__init__.py", line 1258, in _log<br>[Thu Aug 21 22:03:24 2014] [error] [client 198.63.231.28]     self.handle(record)<br>[Thu Aug 21 22:03:24 2014] [error] [client 198.63.231.28]   File "/usr/lib64/python2.7/logging/__init__.py", line 1268, in handle<br>[Thu Aug 21 22:03:24 2014] [error] [client 198.63.231.28]     self.callHandlers(record)<br>[Thu Aug 21 22:03:24 2014] [error] [client 198.63.231.28]   File "/usr/lib64/python2.7/logging/__init__.py", line 1308, in callHandlers<br>[Thu Aug 21 22:03:24 2014] [error] [client 198.63.231.28]     hdlr.handle(record)<br>[Thu Aug 21 22:03:24 2014] [error] [client 198.63.231.28]   File "/usr/lib64/python2.7/logging/__init__.py", line 748, in handle<br>[Thu Aug 21 22:03:24 2014] [error] [client 198.63.231.28]     self.emit(record)<br>[Thu Aug 21 22:03:24 2014] [error] [client 198.63.231.28]   File "/usr/lib/apx-hcc/.venv/lib/python2.7/site-packages/django/utils/log.py", line 112, in emit<br>[Thu Aug 21 22:03:24 2014] [error] [client 198.63.231.28]     html_message = self.include_html and reporter.get_traceback_html() or None<br>[Thu Aug 21 22:03:24 2014] [error] [client 198.63.231.28]   File "/usr/lib/apx-hcc/.venv/lib/python2.7/site-packages/django/views/debug.py", line 298, in get_traceback_html<br>[Thu Aug 21 22:03:24 2014] [error] [client 198.63.231.28]     return t.render(c)<br>[Thu Aug 21 22:03:24 2014] [error] [client 198.63.231.28]   File "/usr/lib/apx-hcc/.venv/lib/python2.7/site-packages/django/template/base.py", line 140, in render<br>[Thu Aug 21 22:03:24 2014] [error] [client 198.63.231.28]     return self._render(context)<br>[Thu Aug 21 22:03:24 2014] [error] [client 198.63.231.28]   File "/usr/lib/apx-hcc/.venv/lib/python2.7/site-packages/django/template/base.py", line 134, in _render<br>[Thu Aug 21 22:03:24 2014] [error] [client 198.63.231.28]     return self.nodelist.render(context)<br>[Thu Aug 21 22:03:24 2014] [error] [client 198.63.231.28]   File "/usr/lib/apx-hcc/.venv/lib/python2.7/site-packages/django/template/base.py", line 830, in render<br>[Thu Aug 21 22:03:24 2014] [error] [client 198.63.231.28]     bit = self.render_node(node, context)<br>[Thu Aug 21 22:03:24 2014] [error] [client 198.63.231.28]   File "/usr/lib/apx-hcc/.venv/lib/python2.7/site-packages/django/template/base.py", line 844, in render_node<br>[Thu Aug 21 22:03:24 2014] [error] [client 198.63.231.28]     return node.render(context)<br>[Thu Aug 21 22:03:24 2014] [error] [client 198.63.231.28]   File "/usr/lib/apx-hcc/.venv/lib/python2.7/site-packages/django/template/defaulttags.py", line 284, in render<br>[Thu Aug 21 22:03:24 2014] [error] [client 198.63.231.28]     return nodelist.render(context)<br>[Thu Aug 21 22:03:24 2014] [error] [client 198.63.231.28]   File "/usr/lib/apx-hcc/.venv/lib/python2.7/site-packages/django/template/base.py", line 830, in render<br>[Thu Aug 21 22:03:24 2014] [error] [client 198.63.231.28]     bit = self.render_node(node, context)<br>[Thu Aug 21 22:03:24 2014] [error] [client 198.63.231.28]   File "/usr/lib/apx-hcc/.venv/lib/python2.7/site-packages/django/template/base.py", line 844, in render_node<br>[Thu Aug 21 22:03:24 2014] [error] [client 198.63.231.28]     return node.render(context)<br>[Thu Aug 21 22:03:24 2014] [error] [client 198.63.231.28]   File "/usr/lib/apx-hcc/.venv/lib/python2.7/site-packages/django/template/base.py", line 881, in render<br>[Thu Aug 21 22:03:24 2014] [error] [client 198.63.231.28]     output = self.filter_expression.resolve(context)<br>[Thu Aug 21 22:03:24 2014] [error] [client 198.63.231.28]   File "/usr/lib/apx-hcc/.venv/lib/python2.7/site-packages/django/template/base.py", line 578, in resolve<br>[Thu Aug 21 22:03:24 2014] [error] [client 198.63.231.28]     obj = self.var.resolve(context)<br>[Thu Aug 21 22:03:24 2014] [error] [client 198.63.231.28]   File "/usr/lib/apx-hcc/.venv/lib/python2.7/site-packages/django/template/base.py", line 728, in resolve<br>[Thu Aug 21 22:03:24 2014] [error] [client 198.63.231.28]     value = self._resolve_lookup(context)<br>[Thu Aug 21 22:03:24 2014] [error] [client 198.63.231.28]   File "/usr/lib/apx-hcc/.venv/lib/python2.7/site-packages/django/template/base.py", line 779, in _resolve_lookup<br>[Thu Aug 21 22:03:24 2014] [error] [client 198.63.231.28]     current = current()<br>[Thu Aug 21 22:03:24 2014] [error] [client 198.63.231.28]   File "/usr/lib/apx-hcc/.venv/lib/python2.7/site-packages/django/http/request.py", line 112, in build_absolute_uri<br>[Thu Aug 21 22:03:24 2014] [error] [client 198.63.231.28]     self.get_host(), self.path)<br>[Thu Aug 21 22:03:24 2014] [error] [client 198.63.231.28]   File "/usr/lib/apx-hcc/.venv/lib/python2.7/site-packages/django/http/request.py", line 72, in get_host<br>[Thu Aug 21 22:03:24 2014] [error] [client 198.63.231.28]     "Invalid HTTP_HOST header (you may need to set ALLOWED_HOSTS): %s" % host)<br>[Thu Aug 21 22:03:24 2014] [error] [client 198.63.231.28] SuspiciousOperation: Invalid HTTP_HOST header (you may need to set ALLOWED_HOSTS): all-s3-us-ic2.digitalhub.com.akadns.net<br>[Thu Aug 21 22:03:34 2014] [error] ('production.hcc', 1408683814, {'sys_module': 'base', 'source': 'django.request', 'host': '64.120.6.122', 'session': None, 'user': u'', 'time': '1408709014647', 'datestamp': '2014-08-22T05:03:34.647637', 'level': 'ERROR', 'sys_host': 'ip-10-172-93-72', 'msecs': 646.9860076904297})<br>[Thu Aug 21 22:03:34 2014] [error] [client 72.247.120.220] mod_wsgi (pid=1758): Exception occurred processing WSGI script '/usr/lib/apx-hcc/hcc_project/hcc_project/wsgi.py'.<br>[Thu Aug 21 22:03:34 2014] [error] [client 72.247.120.220] Traceback (most recent call last):<br>[Thu Aug 21 22:03:34 2014] [error] [client 72.247.120.220]   File "/usr/lib/apx-hcc/.venv/lib/python2.7/site-packages/django/core/handlers/wsgi.py", line 255, in __call__<br>[Thu Aug 21 22:03:34 2014] [error] [client 72.247.120.220]     response = self.get_response(request)<br>[Thu Aug 21 22:03:34 2014] [error] [client 72.247.120.220]   File "/usr/lib/apx-hcc/.venv/lib/python2.7/site-packages/django/core/handlers/base.py", line 178, in get_response<br>[Thu Aug 21 22:03:34 2014] [error] [client 72.247.120.220]     response = self.handle_uncaught_exception(request, resolver, sys.exc_info())<br>[Thu Aug 21 22:03:34 2014] [error] [client 72.247.120.220]   File "/usr/lib/apx-hcc/.venv/lib/python2.7/site-packages/django/core/handlers/base.py", line 212, in handle_uncaught_exception<br>[Thu Aug 21 22:03:34 2014] [error] [client 72.247.120.220]     'request': request<br>[Thu Aug 21 22:03:34 2014] [error] [client 72.247.120.220]   File "/usr/lib64/python2.7/logging/__init__.py", line 1166, in error<br>[Thu Aug 21 22:03:34 2014] [error] [client 72.247.120.220]     self._log(ERROR, msg, args, **kwargs)<br>[Thu Aug 21 22:03:34 2014] [error] [client 72.247.120.220]   File "/usr/lib64/python2.7/logging/__init__.py", line 1258, in _log<br>[Thu Aug 21 22:03:34 2014] [error] [client 72.247.120.220]     self.handle(record)<br>[Thu Aug 21 22:03:34 2014] [error] [client 72.247.120.220]   File "/usr/lib64/python2.7/logging/__init__.py", line 1268, in handle<br>[Thu Aug 21 22:03:34 2014] [error] [client 72.247.120.220]     self.callHandlers(record)<br>[Thu Aug 21 22:03:34 2014] [error] [client 72.247.120.220]   File "/usr/lib64/python2.7/logging/__init__.py", line 1308, in callHandlers<br>[Thu Aug 21 22:03:34 2014] [error] [client 72.247.120.220]     hdlr.handle(record)<br>[Thu Aug 21 22:03:34 2014] [error] [client 72.247.120.220]   File "/usr/lib64/python2.7/logging/__init__.py", line 748, in handle<br>[Thu Aug 21 22:03:34 2014] [error] [client 72.247.120.220]     self.emit(record)<br>[Thu Aug 21 22:03:34 2014] [error] [client 72.247.120.220]   File "/usr/lib/apx-hcc/.venv/lib/python2.7/site-packages/django/utils/log.py", line 112, in emit<br>[Thu Aug 21 22:03:34 2014] [error] [client 72.247.120.220]     html_message = self.include_html and reporter.get_traceback_html() or None<br>[Thu Aug 21 22:03:34 2014] [error] [client 72.247.120.220]   File "/usr/lib/apx-hcc/.venv/lib/python2.7/site-packages/django/views/debug.py", line 298, in get_traceback_html<br>[Thu Aug 21 22:03:34 2014] [error] [client 72.247.120.220]     return t.render(c)<br>[Thu Aug 21 22:03:34 2014] [error] [client 72.247.120.220]   File "/usr/lib/apx-hcc/.venv/lib/python2.7/site-packages/django/template/base.py", line 140, in render<br>[Thu Aug 21 22:03:34 2014] [error] [client 72.247.120.220]     return self._render(context)<br>[Thu Aug 21 22:03:34 2014] [error] [client 72.247.120.220]   File "/usr/lib/apx-hcc/.venv/lib/python2.7/site-packages/django/template/base.py", line 134, in _render<br>[Thu Aug 21 22:03:34 2014] [error] [client 72.247.120.220]     return self.nodelist.render(context)<br>[Thu Aug 21 22:03:34 2014] [error] [client 72.247.120.220]   File "/usr/lib/apx-hcc/.venv/lib/python2.7/site-packages/django/template/base.py", line 830, in render<br>[Thu Aug 21 22:03:34 2014] [error] [client 72.247.120.220]     bit = self.render_node(node, context)<br>[Thu Aug 21 22:03:34 2014] [error] [client 72.247.120.220]   File "/usr/lib/apx-hcc/.venv/lib/python2.7/site-packages/django/template/base.py", line 844, in render_node<br>[Thu Aug 21 22:03:34 2014] [error] [client 72.247.120.220]     return node.render(context)<br>[Thu Aug 21 22:03:34 2014] [error] [client 72.247.120.220]   File "/usr/lib/apx-hcc/.venv/lib/python2.7/site-packages/django/template/defaulttags.py", line 284, in render<br>[Thu Aug 21 22:03:34 2014] [error] [client 72.247.120.220]     return nodelist.render(context)<br>[Thu Aug 21 22:03:34 2014] [error] [client 72.247.120.220]   File "/usr/lib/apx-hcc/.venv/lib/python2.7/site-packages/django/template/base.py", line 830, in render<br>[Thu Aug 21 22:03:34 2014] [error] [client 72.247.120.220]     bit = self.render_node(node, context)<br>[Thu Aug 21 22:03:34 2014] [error] [client 72.247.120.220]   File "/usr/lib/apx-hcc/.venv/lib/python2.7/site-packages/django/template/base.py", line 844, in render_node<br>[Thu Aug 21 22:03:34 2014] [error] [client 72.247.120.220]     return node.render(context)<br>[Thu Aug 21 22:03:34 2014] [error] [client 72.247.120.220]   File "/usr/lib/apx-hcc/.venv/lib/python2.7/site-packages/django/template/base.py", line 881, in render<br>[Thu Aug 21 22:03:34 2014] [error] [client 72.247.120.220]     output = self.filter_expression.resolve(context)<br>[Thu Aug 21 22:03:34 2014] [error] [client 72.247.120.220]   File "/usr/lib/apx-hcc/.venv/lib/python2.7/site-packages/django/template/base.py", line 578, in resolve<br>[Thu Aug 21 22:03:34 2014] [error] [client 72.247.120.220]     obj = self.var.resolve(context)<br>[Thu Aug 21 22:03:34 2014] [error] [client 72.247.120.220]   File "/usr/lib/apx-hcc/.venv/lib/python2.7/site-packages/django/template/base.py", line 728, in resolve<br>[Thu Aug 21 22:03:34 2014] [error] [client 72.247.120.220]     value = self._resolve_lookup(context)<br>[Thu Aug 21 22:03:34 2014] [error] [client 72.247.120.220]   File "/usr/lib/apx-hcc/.venv/lib/python2.7/site-packages/django/template/base.py", line 779, in _resolve_lookup<br>[Thu Aug 21 22:03:34 2014] [error] [client 72.247.120.220]     current = current()<br>[Thu Aug 21 22:03:34 2014] [error] [client 72.247.120.220]   File "/usr/lib/apx-hcc/.venv/lib/python2.7/site-packages/django/http/request.py", line 112, in build_absolute_uri<br>[Thu Aug 21 22:03:34 2014] [error] [client 72.247.120.220]     self.get_host(), self.path)<br>[Thu Aug 21 22:03:34 2014] [error] [client 72.247.120.220]   File "/usr/lib/apx-hcc/.venv/lib/python2.7/site-packages/django/http/request.py", line 72, in get_host<br>[Thu Aug 21 22:03:34 2014] [error] [client 72.247.120.220]     "Invalid HTTP_HOST header (you may need to set ALLOWED_HOSTS): %s" % host)<br>[Thu Aug 21 22:03:34 2014] [error] [client 72.247.120.220] SuspiciousOperation: Invalid HTTP_HOST header (you may need to set ALLOWED_HOSTS): all-s3-us-ic2.digitalhub.com.akadns.net<br>[Thu Aug 21 22:03:38 2014] [error] ('production.hcc', 1408683818, {'sys_module': 'base', 'source': 'django.request', 'host': '72.46.140.186', 'session': None, 'user': u'', 'time': '1408709018341', 'datestamp': '2014-08-22T05:03:38.341945', 'level': 'ERROR', 'sys_host': 'ip-10-172-93-72', 'msecs': 341.3560390472412})<br>[Thu Aug 21 22:03:38 2014] [error] [client 205.185.205.132] mod_wsgi (pid=1758): Exception occurred processing WSGI script '/usr/lib/apx-hcc/hcc_project/hcc_project/wsgi.py'.<br>[Thu Aug 21 22:03:38 2014] [error] [client 205.185.205.132] Traceback (most recent call last):<br>[Thu Aug 21 22:03:38 2014] [error] [client 205.185.205.132]   File "/usr/lib/apx-hcc/.venv/lib/python2.7/site-packages/django/core/handlers/wsgi.py", line 255, in __call__<br>[Thu Aug 21 22:03:38 2014] [error] [client 205.185.205.132]     response = self.get_response(request)<br>[Thu Aug 21 22:03:38 2014] [error] [client 205.185.205.132]   File "/usr/lib/apx-hcc/.venv/lib/python2.7/site-packages/django/core/handlers/base.py", line 178, in get_response<br>[Thu Aug 21 22:03:38 2014] [error] [client 205.185.205.132]     response = self.handle_uncaught_exception(request, resolver, sys.exc_info())<br>[Thu Aug 21 22:03:38 2014] [error] [client 205.185.205.132]   File "/usr/lib/apx-hcc/.venv/lib/python2.7/site-packages/django/core/handlers/base.py", line 212, in handle_uncaught_exception<br>[Thu Aug 21 22:03:38 2014] [error] [client 205.185.205.132]     'request': request<br>[Thu Aug 21 22:03:38 2014] [error] [client 205.185.205.132]   File "/usr/lib64/python2.7/logging/__init__.py", line 1166, in error<br>[Thu Aug 21 22:03:38 2014] [error] [client 205.185.205.132]     self._log(ERROR, msg, args, **kwargs)<br>[Thu Aug 21 22:03:38 2014] [error] [client 205.185.205.132]   File "/usr/lib64/python2.7/logging/__init__.py", line 1258, in _log<br>[Thu Aug 21 22:03:38 2014] [error] [client 205.185.205.132]     self.handle(record)<br>[Thu Aug 21 22:03:38 2014] [error] [client 205.185.205.132]   File "/usr/lib64/python2.7/logging/__init__.py", line 1268, in handle<br>[Thu Aug 21 22:03:38 2014] [error] [client 205.185.205.132]     self.callHandlers(record)<br>[Thu Aug 21 22:03:38 2014] [error] [client 205.185.205.132]   File "/usr/lib64/python2.7/logging/__init__.py", line 1308, in callHandlers<br>[Thu Aug 21 22:03:38 2014] [error] [client 205.185.205.132]     hdlr.handle(record)<br>[Thu Aug 21 22:03:38 2014] [error] [client 205.185.205.132]   File "/usr/lib64/python2.7/logging/__init__.py", line 748, in handle<br>[Thu Aug 21 22:03:38 2014] [error] [client 205.185.205.132]     self.emit(record)<br>[Thu Aug 21 22:03:38 2014] [error] [client 205.185.205.132]   File "/usr/lib/apx-hcc/.venv/lib/python2.7/site-packages/django/utils/log.py", line 112, in emit<br>[Thu Aug 21 22:03:38 2014] [error] [client 205.185.205.132]     html_message = self.include_html and reporter.get_traceback_html() or None<br>[Thu Aug 21 22:03:38 2014] [error] [client 205.185.205.132]   File "/usr/lib/apx-hcc/.venv/lib/python2.7/site-packages/django/views/debug.py", line 298, in get_traceback_html<br>[Thu Aug 21 22:03:38 2014] [error] [client 205.185.205.132]     return t.render(c)<br>[Thu Aug 21 22:03:38 2014] [error] [client 205.185.205.132]   File "/usr/lib/apx-hcc/.venv/lib/python2.7/site-packages/django/template/base.py", line 140, in render<br>[Thu Aug 21 22:03:38 2014] [error] [client 205.185.205.132]     return self._render(context)<br>[Thu Aug 21 22:03:38 2014] [error] [client 205.185.205.132]   File "/usr/lib/apx-hcc/.venv/lib/python2.7/site-packages/django/template/base.py", line 134, in _render<br>[Thu Aug 21 22:03:38 2014] [error] [client 205.185.205.132]     return self.nodelist.render(context)<br>[Thu Aug 21 22:03:38 2014] [error] [client 205.185.205.132]   File "/usr/lib/apx-hcc/.venv/lib/python2.7/site-packages/django/template/base.py", line 830, in render<br>[Thu Aug 21 22:03:38 2014] [error] [client 205.185.205.132]     bit = self.render_node(node, context)<br>[Thu Aug 21 22:03:38 2014] [error] [client 205.185.205.132]   File "/usr/lib/apx-hcc/.venv/lib/python2.7/site-packages/django/template/base.py", line 844, in render_node<br>[Thu Aug 21 22:03:38 2014] [error] [client 205.185.205.132]     return node.render(context)<br>[Thu Aug 21 22:03:38 2014] [error] [client 205.185.205.132]   File "/usr/lib/apx-hcc/.venv/lib/python2.7/site-packages/django/template/defaulttags.py", line 284, in render<br>[Thu Aug 21 22:03:38 2014] [error] [client 205.185.205.132]     return nodelist.render(context)<br>[Thu Aug 21 22:03:38 2014] [error] [client 205.185.205.132]   File "/usr/lib/apx-hcc/.venv/lib/python2.7/site-packages/django/template/base.py", line 830, in render<br>[Thu Aug 21 22:03:38 2014] [error] [client 205.185.205.132]     bit = self.render_node(node, context)<br>[Thu Aug 21 22:03:38 2014] [error] [client 205.185.205.132]   File "/usr/lib/apx-hcc/.venv/lib/python2.7/site-packages/django/template/base.py", line 844, in render_node<br>[Thu Aug 21 22:03:38 2014] [error] [client 205.185.205.132]     return node.render(context)<br>[Thu Aug 21 22:03:38 2014] [error] [client 205.185.205.132]   File "/usr/lib/apx-hcc/.venv/lib/python2.7/site-packages/django/template/base.py", line 881, in render<br>[Thu Aug 21 22:03:38 2014] [error] [client 205.185.205.132]     output = self.filter_expression.resolve(context)<br>[Thu Aug 21 22:03:38 2014] [error] [client 205.185.205.132]   File "/usr/lib/apx-hcc/.venv/lib/python2.7/site-packages/django/template/base.py", line 578, in resolve<br>[Thu Aug 21 22:03:38 2014] [error] [client 205.185.205.132]     obj = self.var.resolve(context)<br>[Thu Aug 21 22:03:38 2014] [error] [client 205.185.205.132]   File "/usr/lib/apx-hcc/.venv/lib/python2.7/site-packages/django/template/base.py", line 728, in resolve<br>[Thu Aug 21 22:03:38 2014] [error] [client 205.185.205.132]     value = self._resolve_lookup(context)<br>[Thu Aug 21 22:03:38 2014] [error] [client 205.185.205.132]   File "/usr/lib/apx-hcc/.venv/lib/python2.7/site-packages/django/template/base.py", line 779, in _resolve_lookup<br>[Thu Aug 21 22:03:38 2014] [error] [client 205.185.205.132]     current = current()<br>[Thu Aug 21 22:03:38 2014] [error] [client 205.185.205.132]   File "/usr/lib/apx-hcc/.venv/lib/python2.7/site-packages/django/http/request.py", line 112, in build_absolute_uri<br>[Thu Aug 21 22:03:38 2014] [error] [client 205.185.205.132]     self.get_host(), self.path)<br>[Thu Aug 21 22:03:38 2014] [error] [client 205.185.205.132]   File "/usr/lib/apx-hcc/.venv/lib/python2.7/site-packages/django/http/request.py", line 72, in get_host<br>[Thu Aug 21 22:03:38 2014] [error] [client 205.185.205.132]     "Invalid HTTP_HOST header (you may need to set ALLOWED_HOSTS): %s" % host)<br>[Thu Aug 21 22:03:38 2014] [error] [client 205.185.205.132] SuspiciousOperation: Invalid HTTP_HOST header (you may need to set ALLOWED_HOSTS): all-s3-us-ic2.digitalhub.com.akadns.net<br>[Thu Aug 21 22:03:39 2014] [error] ('production.hcc', 1408683819, {'sys_module': 'base', 'source': 'django.request', 'host': '64.120.6.122', 'session': None, 'user': u'', 'time': '1408709019388', 'datestamp': '2014-08-22T05:03:39.388403', 'level': 'ERROR', 'sys_host': 'ip-10-172-93-72', 'msecs': 387.8040313720703})<br>[Thu Aug 21 22:03:39 2014] [error] [client 77.67.85.53] mod_wsgi (pid=1758): Exception occurred processing WSGI script '/usr/lib/apx-hcc/hcc_project/hcc_project/wsgi.py'.<br>[Thu Aug 21 22:03:39 2014] [error] [client 77.67.85.53] Traceback (most recent call last):<br>[Thu Aug 21 22:03:39 2014] [error] [client 77.67.85.53]   File "/usr/lib/apx-hcc/.venv/lib/python2.7/site-packages/django/core/handlers/wsgi.py", line 255, in __call__<br>[Thu Aug 21 22:03:39 2014] [error] [client 77.67.85.53]     response = self.get_response(request)<br>[Thu Aug 21 22:03:39 2014] [error] [client 77.67.85.53]   File "/usr/lib/apx-hcc/.venv/lib/python2.7/site-packages/django/core/handlers/base.py", line 178, in get_response<br>[Thu Aug 21 22:03:39 2014] [error] [client 77.67.85.53]     response = self.handle_uncaught_exception(request, resolver, sys.exc_info())<br>[Thu Aug 21 22:03:39 2014] [error] [client 77.67.85.53]   File "/usr/lib/apx-hcc/.venv/lib/python2.7/site-packages/django/core/handlers/base.py", line 212, in handle_uncaught_exception<br>[Thu Aug 21 22:03:39 2014] [error] [client 77.67.85.53]     'request': request<br>[Thu Aug 21 22:03:39 2014] [error] [client 77.67.85.53]   File "/usr/lib64/python2.7/logging/__init__.py", line 1166, in error<br>[Thu Aug 21 22:03:39 2014] [error] [client 77.67.85.53]     self._log(ERROR, msg, args, **kwargs)<br>[Thu Aug 21 22:03:39 2014] [error] [client 77.67.85.53]   File "/usr/lib64/python2.7/logging/__init__.py", line 1258, in _log<br>[Thu Aug 21 22:03:39 2014] [error] [client 77.67.85.53]     self.handle(record)<br>[Thu Aug 21 22:03:39 2014] [error] [client 77.67.85.53]   File "/usr/lib64/python2.7/logging/__init__.py", line 1268, in handle<br>[Thu Aug 21 22:03:39 2014] [error] [client 77.67.85.53]     self.callHandlers(record)<br>[Thu Aug 21 22:03:39 2014] [error] [client 77.67.85.53]   File "/usr/lib64/python2.7/logging/__init__.py", line 1308, in callHandlers<br>[Thu Aug 21 22:03:39 2014] [error] [client 77.67.85.53]     hdlr.handle(record)<br>[Thu Aug 21 22:03:39 2014] [error] [client 77.67.85.53]   File "/usr/lib64/python2.7/logging/__init__.py", line 748, in handle<br>[Thu Aug 21 22:03:39 2014] [error] [client 77.67.85.53]     self.emit(record)<br>[Thu Aug 21 22:03:39 2014] [error] [client 77.67.85.53]   File "/usr/lib/apx-hcc/.venv/lib/python2.7/site-packages/django/utils/log.py", line 112, in emit<br>[Thu Aug 21 22:03:39 2014] [error] [client 77.67.85.53]     html_message = self.include_html and reporter.get_traceback_html() or None<br>[Thu Aug 21 22:03:39 2014] [error] [client 77.67.85.53]   File "/usr/lib/apx-hcc/.venv/lib/python2.7/site-packages/django/views/debug.py", line 298, in get_traceback_html<br>[Thu Aug 21 22:03:39 2014] [error] [client 77.67.85.53]     return t.render(c)<br>[Thu Aug 21 22:03:39 2014] [error] [client 77.67.85.53]   File "/usr/lib/apx-hcc/.venv/lib/python2.7/site-packages/django/template/base.py", line 140, in render<br>[Thu Aug 21 22:03:39 2014] [error] [client 77.67.85.53]     return self._render(context)<br>[Thu Aug 21 22:03:39 2014] [error] [client 77.67.85.53]   File "/usr/lib/apx-hcc/.venv/lib/python2.7/site-packages/django/template/base.py", line 134, in _render<br>[Thu Aug 21 22:03:39 2014] [error] [client 77.67.85.53]     return self.nodelist.render(context)<br>[Thu Aug 21 22:03:39 2014] [error] [client 77.67.85.53]   File "/usr/lib/apx-hcc/.venv/lib/python2.7/site-packages/django/template/base.py", line 830, in render<br>[Thu Aug 21 22:03:39 2014] [error] [client 77.67.85.53]     bit = self.render_node(node, context)<br>[Thu Aug 21 22:03:39 2014] [error] [client 77.67.85.53]   File "/usr/lib/apx-hcc/.venv/lib/python2.7/site-packages/django/template/base.py", line 844, in render_node<br>[Thu Aug 21 22:03:39 2014] [error] [client 77.67.85.53]     return node.render(context)<br>[Thu Aug 21 22:03:39 2014] [error] [client 77.67.85.53]   File "/usr/lib/apx-hcc/.venv/lib/python2.7/site-packages/django/template/defaulttags.py", line 284, in render<br>[Thu Aug 21 22:03:39 2014] [error] [client 77.67.85.53]     return nodelist.render(context)<br>[Thu Aug 21 22:03:39 2014] [error] [client 77.67.85.53]   File "/usr/lib/apx-hcc/.venv/lib/python2.7/site-packages/django/template/base.py", line 830, in render<br>[Thu Aug 21 22:03:39 2014] [error] [client 77.67.85.53]     bit = self.render_node(node, context)<br>[Thu Aug 21 22:03:39 2014] [error] [client 77.67.85.53]   File "/usr/lib/apx-hcc/.venv/lib/python2.7/site-packages/django/template/base.py", line 844, in render_node<br>[Thu Aug 21 22:03:39 2014] [error] [client 77.67.85.53]     return node.render(context)<br>[Thu Aug 21 22:03:39 2014] [error] [client 77.67.85.53]   File "/usr/lib/apx-hcc/.venv/lib/python2.7/site-packages/django/template/base.py", line 881, in render<br>[Thu Aug 21 22:03:39 2014] [error] [client 77.67.85.53]     output = self.filter_expression.resolve(context)<br>[Thu Aug 21 22:03:39 2014] [error] [client 77.67.85.53]   File "/usr/lib/apx-hcc/.venv/lib/python2.7/site-packages/django/template/base.py", line 578, in resolve<br>[Thu Aug 21 22:03:39 2014] [error] [client 77.67.85.53]     obj = self.var.resolve(context)<br>[Thu Aug 21 22:03:39 2014] [error] [client 77.67.85.53]   File "/usr/lib/apx-hcc/.venv/lib/python2.7/site-packages/django/template/base.py", line 728, in resolve<br>[Thu Aug 21 22:03:39 2014] [error] [client 77.67.85.53]     value = self._resolve_lookup(context)<br>[Thu Aug 21 22:03:39 2014] [error] [client 77.67.85.53]   File "/usr/lib/apx-hcc/.venv/lib/python2.7/site-packages/django/template/base.py", line 779, in _resolve_lookup<br>[Thu Aug 21 22:03:39 2014] [error] [client 77.67.85.53]     current = current()<br>[Thu Aug 21 22:03:39 2014] [error] [client 77.67.85.53]   File "/usr/lib/apx-hcc/.venv/lib/python2.7/site-packages/django/http/request.py", line 112, in build_absolute_uri<br>[Thu Aug 21 22:03:39 2014] [error] [client 77.67.85.53]     self.get_host(), self.path)<br>[Thu Aug 21 22:03:39 2014] [error] [client 77.67.85.53]   File "/usr/lib/apx-hcc/.venv/lib/python2.7/site-packages/django/http/request.py", line 72, in get_host<br>[Thu Aug 21 22:03:39 2014] [error] [client 77.67.85.53]     "Invalid HTTP_HOST header (you may need to set ALLOWED_HOSTS): %s" % host)<br>[Thu Aug 21 22:03:39 2014] [error] [client 77.67.85.53] SuspiciousOperation: Invalid HTTP_HOST header (you may need to set ALLOWED_HOSTS): all-s3-us-ic2.digitalhub.com.akadns.net<br>[Thu Aug 21 22:03:49 2014] [error] ('production.hcc', 1408683829, {'sys_module': 'base', 'source': 'django.request', 'host': '72.46.140.186', 'session': None, 'user': u'', 'time': '1408709029662', 'datestamp': '2014-08-22T05:03:49.662020', 'level': 'ERROR', 'sys_host': 'ip-10-172-93-72', 'msecs': 661.4339351654053})<br>[Thu Aug 21 22:03:49 2014] [error] [client 204.2.160.183] mod_wsgi (pid=1758): Exception occurred processing WSGI script '/usr/lib/apx-hcc/hcc_project/hcc_project/wsgi.py'.<br>[Thu Aug 21 22:03:49 2014] [error] [client 204.2.160.183] Traceback (most recent call last):<br>[Thu Aug 21 22:03:49 2014] [error] [client 204.2.160.183]   File "/usr/lib/apx-hcc/.venv/lib/python2.7/site-packages/django/core/handlers/wsgi.py", line 255, in __call__<br>[Thu Aug 21 22:03:49 2014] [error] [client 204.2.160.183]     response = self.get_response(request)<br>[Thu Aug 21 22:03:49 2014] [error] [client 204.2.160.183]   File "/usr/lib/apx-hcc/.venv/lib/python2.7/site-packages/django/core/handlers/base.py", line 178, in get_response<br>[Thu Aug 21 22:03:49 2014] [error] [client 204.2.160.183]     response = self.handle_uncaught_exception(request, resolver, sys.exc_info())<br>[Thu Aug 21 22:03:49 2014] [error] [client 204.2.160.183]   File "/usr/lib/apx-hcc/.venv/lib/python2.7/site-packages/django/core/handlers/base.py", line 212, in handle_uncaught_exception<br>[Thu Aug 21 22:03:49 2014] [error] [client 204.2.160.183]     'request': request<br>[Thu Aug 21 22:03:49 2014] [error] [client 204.2.160.183]   File "/usr/lib64/python2.7/logging/__init__.py", line 1166, in error<br>[Thu Aug 21 22:03:49 2014] [error] [client 204.2.160.183]     self._log(ERROR, msg, args, **kwargs)<br>[Thu Aug 21 22:03:49 2014] [error] [client 204.2.160.183]   File "/usr/lib64/python2.7/logging/__init__.py", line 1258, in _log<br>[Thu Aug 21 22:03:49 2014] [error] [client 204.2.160.183]     self.handle(record)<br>[Thu Aug 21 22:03:49 2014] [error] [client 204.2.160.183]   File "/usr/lib64/python2.7/logging/__init__.py", line 1268, in handle<br>[Thu Aug 21 22:03:49 2014] [error] [client 204.2.160.183]     self.callHandlers(record)<br>[Thu Aug 21 22:03:49 2014] [error] [client 204.2.160.183]   File "/usr/lib64/python2.7/logging/__init__.py", line 1308, in callHandlers<br>[Thu Aug 21 22:03:49 2014] [error] [client 204.2.160.183]     hdlr.handle(record)<br>[Thu Aug 21 22:03:49 2014] [error] [client 204.2.160.183]   File "/usr/lib64/python2.7/logging/__init__.py", line 748, in handle<br>[Thu Aug 21 22:03:49 2014] [error] [client 204.2.160.183]     self.emit(record)<br>[Thu Aug 21 22:03:49 2014] [error] [client 204.2.160.183]   File "/usr/lib/apx-hcc/.venv/lib/python2.7/site-packages/django/utils/log.py", line 112, in emit<br>[Thu Aug 21 22:03:49 2014] [error] [client 204.2.160.183]     html_message = self.include_html and reporter.get_traceback_html() or None<br>[Thu Aug 21 22:03:49 2014] [error] [client 204.2.160.183]   File "/usr/lib/apx-hcc/.venv/lib/python2.7/site-packages/django/views/debug.py", line 298, in get_traceback_html<br>[Thu Aug 21 22:03:49 2014] [error] [client 204.2.160.183]     return t.render(c)<br>[Thu Aug 21 22:03:49 2014] [error] [client 204.2.160.183]   File "/usr/lib/apx-hcc/.venv/lib/python2.7/site-packages/django/template/base.py", line 140, in render<br>[Thu Aug 21 22:03:49 2014] [error] [client 204.2.160.183]     return self._render(context)<br>[Thu Aug 21 22:03:49 2014] [error] [client 204.2.160.183]   File "/usr/lib/apx-hcc/.venv/lib/python2.7/site-packages/django/template/base.py", line 134, in _render<br>[Thu Aug 21 22:03:49 2014] [error] [client 204.2.160.183]     return self.nodelist.render(context)<br>[Thu Aug 21 22:03:49 2014] [error] [client 204.2.160.183]   File "/usr/lib/apx-hcc/.venv/lib/python2.7/site-packages/django/template/base.py", line 830, in render<br>[Thu Aug 21 22:03:49 2014] [error] [client 204.2.160.183]     bit = self.render_node(node, context)<br>[Thu Aug 21 22:03:49 2014] [error] [client 204.2.160.183]   File "/usr/lib/apx-hcc/.venv/lib/python2.7/site-packages/django/template/base.py", line 844, in render_node<br>[Thu Aug 21 22:03:49 2014] [error] [client 204.2.160.183]     return node.render(context)<br>[Thu Aug 21 22:03:49 2014] [error] [client 204.2.160.183]   File "/usr/lib/apx-hcc/.venv/lib/python2.7/site-packages/django/template/defaulttags.py", line 284, in render<br>[Thu Aug 21 22:03:49 2014] [error] [client 204.2.160.183]     return nodelist.render(context)<br>[Thu Aug 21 22:03:49 2014] [error] [client 204.2.160.183]   File "/usr/lib/apx-hcc/.venv/lib/python2.7/site-packages/django/template/base.py", line 830, in render<br>[Thu Aug 21 22:03:49 2014] [error] [client 204.2.160.183]     bit = self.render_node(node, context)<br>[Thu Aug 21 22:03:49 2014] [error] [client 204.2.160.183]   File "/usr/lib/apx-hcc/.venv/lib/python2.7/site-packages/django/template/base.py", line 844, in render_node<br>[Thu Aug 21 22:03:49 2014] [error] [client 204.2.160.183]     return node.render(context)<br>[Thu Aug 21 22:03:49 2014] [error] [client 204.2.160.183]   File "/usr/lib/apx-hcc/.venv/lib/python2.7/site-packages/django/template/base.py", line 881, in render<br>[Thu Aug 21 22:03:49 2014] [error] [client 204.2.160.183]     output = self.filter_expression.resolve(context)<br>[Thu Aug 21 22:03:49 2014] [error] [client 204.2.160.183]   File "/usr/lib/apx-hcc/.venv/lib/python2.7/site-packages/django/template/base.py", line 578, in resolve<br>[Thu Aug 21 22:03:49 2014] [error] [client 204.2.160.183]     obj = self.var.resolve(context)<br>[Thu Aug 21 22:03:49 2014] [error] [client 204.2.160.183]   File "/usr/lib/apx-hcc/.venv/lib/python2.7/site-packages/django/template/base.py", line 728, in resolve<br>[Thu Aug 21 22:03:49 2014] [error] [client 204.2.160.183]     value = self._resolve_lookup(context)<br>[Thu Aug 21 22:03:49 2014] [error] [client 204.2.160.183]   File "/usr/lib/apx-hcc/.venv/lib/python2.7/site-packages/django/template/base.py", line 779, in _resolve_lookup<br>[Thu Aug 21 22:03:49 2014] [error] [client 204.2.160.183]     current = current()<br>[Thu Aug 21 22:03:49 2014] [error] [client 204.2.160.183]   File "/usr/lib/apx-hcc/.venv/lib/python2.7/site-packages/django/http/request.py", line 112, in build_absolute_uri<br>[Thu Aug 21 22:03:49 2014] [error] [client 204.2.160.183]     self.get_host(), self.path)<br>[Thu Aug 21 22:03:49 2014] [error] [client 204.2.160.183]   File "/usr/lib/apx-hcc/.venv/lib/python2.7/site-packages/django/http/request.py", line 72, in get_host<br>[Thu Aug 21 22:03:49 2014] [error] [client 204.2.160.183]     "Invalid HTTP_HOST header (you may need to set ALLOWED_HOSTS): %s" % host)<br>[Thu Aug 21 22:03:49 2014] [error] [client 204.2.160.183] SuspiciousOperation: Invalid HTTP_HOST header (you may need to set ALLOWED_HOSTS): all-s3-us-ic2.digitalhub.com.akadns.net<br>[Thu Aug 21 22:03:54 2014] [error] ('production.hcc', 1408683834, {'sys_module': 'base', 'source': 'django.request', 'host': '64.120.6.122', 'session': None, 'user': u'', 'time': '1408709034928', 'datestamp': '2014-08-22T05:03:54.928557', 'level': 'ERROR', 'sys_host': 'ip-10-172-93-72', 'msecs': 927.947998046875})<br>[Thu Aug 21 22:03:54 2014] [error] [client 198.63.231.28] mod_wsgi (pid=1758): Exception occurred processing WSGI script '/usr/lib/apx-hcc/hcc_project/hcc_project/wsgi.py'.<br>[Thu Aug 21 22:03:54 2014] [error] [client 198.63.231.28] Traceback (most recent call last):<br>[Thu Aug 21 22:03:54 2014] [error] [client 198.63.231.28]   File "/usr/lib/apx-hcc/.venv/lib/python2.7/site-packages/django/core/handlers/wsgi.py", line 255, in __call__<br>[Thu Aug 21 22:03:54 2014] [error] [client 198.63.231.28]     response = self.get_response(request)<br>[Thu Aug 21 22:03:54 2014] [error] [client 198.63.231.28]   File "/usr/lib/apx-hcc/.venv/lib/python2.7/site-packages/django/core/handlers/base.py", line 178, in get_response<br>[Thu Aug 21 22:03:54 2014] [error] [client 198.63.231.28]     response = self.handle_uncaught_exception(request, resolver, sys.exc_info())<br>[Thu Aug 21 22:03:54 2014] [error] [client 198.63.231.28]   File "/usr/lib/apx-hcc/.venv/lib/python2.7/site-packages/django/core/handlers/base.py", line 212, in handle_uncaught_exception<br>[Thu Aug 21 22:03:54 2014] [error] [client 198.63.231.28]     'request': request<br>[Thu Aug 21 22:03:54 2014] [error] [client 198.63.231.28]   File "/usr/lib64/python2.7/logging/__init__.py", line 1166, in error<br>[Thu Aug 21 22:03:54 2014] [error] [client 198.63.231.28]     self._log(ERROR, msg, args, **kwargs)<br>[Thu Aug 21 22:03:54 2014] [error] [client 198.63.231.28]   File "/usr/lib64/python2.7/logging/__init__.py", line 1258, in _log<br>[Thu Aug 21 22:03:54 2014] [error] [client 198.63.231.28]     self.handle(record)<br>[Thu Aug 21 22:03:54 2014] [error] [client 198.63.231.28]   File "/usr/lib64/python2.7/logging/__init__.py", line 1268, in handle<br>[Thu Aug 21 22:03:54 2014] [error] [client 198.63.231.28]     self.callHandlers(record)<br>[Thu Aug 21 22:03:54 2014] [error] [client 198.63.231.28]   File "/usr/lib64/python2.7/logging/__init__.py", line 1308, in callHandlers<br>[Thu Aug 21 22:03:54 2014] [error] [client 198.63.231.28]     hdlr.handle(record)<br>[Thu Aug 21 22:03:54 2014] [error] [client 198.63.231.28]   File "/usr/lib64/python2.7/logging/__init__.py", line 748, in handle<br>[Thu Aug 21 22:03:54 2014] [error] [client 198.63.231.28]     self.emit(record)<br>[Thu Aug 21 22:03:54 2014] [error] [client 198.63.231.28]   File "/usr/lib/apx-hcc/.venv/lib/python2.7/site-packages/django/utils/log.py", line 112, in emit<br>[Thu Aug 21 22:03:54 2014] [error] [client 198.63.231.28]     html_message = self.include_html and reporter.get_traceback_html() or None<br>[Thu Aug 21 22:03:54 2014] [error] [client 198.63.231.28]   File "/usr/lib/apx-hcc/.venv/lib/python2.7/site-packages/django/views/debug.py", line 298, in get_traceback_html<br>[Thu Aug 21 22:03:54 2014] [error] [client 198.63.231.28]     return t.render(c)<br>[Thu Aug 21 22:03:54 2014] [error] [client 198.63.231.28]   File "/usr/lib/apx-hcc/.venv/lib/python2.7/site-packages/django/template/base.py", line 140, in render<br>[Thu Aug 21 22:03:54 2014] [error] [client 198.63.231.28]     return self._render(context)<br>[Thu Aug 21 22:03:54 2014] [error] [client 198.63.231.28]   File "/usr/lib/apx-hcc/.venv/lib/python2.7/site-packages/django/template/base.py", line 134, in _render<br>[Thu Aug 21 22:03:54 2014] [error] [client 198.63.231.28]     return self.nodelist.render(context)<br>[Thu Aug 21 22:03:54 2014] [error] [client 198.63.231.28]   File "/usr/lib/apx-hcc/.venv/lib/python2.7/site-packages/django/template/base.py", line 830, in render<br>[Thu Aug 21 22:03:54 2014] [error] [client 198.63.231.28]     bit = self.render_node(node, context)<br>[Thu Aug 21 22:03:54 2014] [error] [client 198.63.231.28]   File "/usr/lib/apx-hcc/.venv/lib/python2.7/site-packages/django/template/base.py", line 844, in render_node<br>[Thu Aug 21 22:03:54 2014] [error] [client 198.63.231.28]     return node.render(context)<br>[Thu Aug 21 22:03:54 2014] [error] [client 198.63.231.28]   File "/usr/lib/apx-hcc/.venv/lib/python2.7/site-packages/django/template/defaulttags.py", line 284, in render<br>[Thu Aug 21 22:03:54 2014] [error] [client 198.63.231.28]     return nodelist.render(context)<br>[Thu Aug 21 22:03:54 2014] [error] [client 198.63.231.28]   File "/usr/lib/apx-hcc/.venv/lib/python2.7/site-packages/django/template/base.py", line 830, in render<br>[Thu Aug 21 22:03:54 2014] [error] [client 198.63.231.28]     bit = self.render_node(node, context)<br>[Thu Aug 21 22:03:54 2014] [error] [client 198.63.231.28]   File "/usr/lib/apx-hcc/.venv/lib/python2.7/site-packages/django/template/base.py", line 844, in render_node<br>[Thu Aug 21 22:03:54 2014] [error] [client 198.63.231.28]     return node.render(context)<br>[Thu Aug 21 22:03:54 2014] [error] [client 198.63.231.28]   File "/usr/lib/apx-hcc/.venv/lib/python2.7/site-packages/django/template/base.py", line 881, in render<br>[Thu Aug 21 22:03:54 2014] [error] [client 198.63.231.28]     output = self.filter_expression.resolve(context)<br>[Thu Aug 21 22:03:54 2014] [error] [client 198.63.231.28]   File "/usr/lib/apx-hcc/.venv/lib/python2.7/site-packages/django/template/base.py", line 578, in resolve<br>[Thu Aug 21 22:03:54 2014] [error] [client 198.63.231.28]     obj = self.var.resolve(context)<br>[Thu Aug 21 22:03:54 2014] [error] [client 198.63.231.28]   File "/usr/lib/apx-hcc/.venv/lib/python2.7/site-packages/django/template/base.py", line 728, in resolve<br>[Thu Aug 21 22:03:54 2014] [error] [client 198.63.231.28]     value = self._resolve_lookup(context)<br>[Thu Aug 21 22:03:54 2014] [error] [client 198.63.231.28]   File "/usr/lib/apx-hcc/.venv/lib/python2.7/site-packages/django/template/base.py", line 779, in _resolve_lookup<br>[Thu Aug 21 22:03:54 2014] [error] [client 198.63.231.28]     current = current()<br>[Thu Aug 21 22:03:54 2014] [error] [client 198.63.231.28]   File "/usr/lib/apx-hcc/.venv/lib/python2.7/site-packages/django/http/request.py", line 112, in build_absolute_uri<br>[Thu Aug 21 22:03:54 2014] [error] [client 198.63.231.28]     self.get_host(), self.path)<br>[Thu Aug 21 22:03:54 2014] [error] [client 198.63.231.28]   File "/usr/lib/apx-hcc/.venv/lib/python2.7/site-packages/django/http/request.py", line 72, in get_host<br>[Thu Aug 21 22:03:54 2014] [error] [client 198.63.231.28]     "Invalid HTTP_HOST header (you may need to set ALLOWED_HOSTS): %s" % host)<br>[Thu Aug 21 22:03:54 2014] [error] [client 198.63.231.28] SuspiciousOperation: Invalid HTTP_HOST header (you may need to set ALLOWED_HOSTS): all-s3-us-ic2.digitalhub.com.akadns.net<br>[Thu Aug 21 22:04:05 2014] [error] ('production.hcc', 1408683845, {'sys_module': 'base', 'source': 'django.request', 'host': '72.46.140.186', 'session': None, 'user': u'', 'time': '1408709045023', 'datestamp': '2014-08-22T05:04:05.023084', 'level': 'ERROR', 'sys_host': 'ip-10-172-93-72', 'msecs': 22.474050521850586})<br>[Thu Aug 21 22:04:05 2014] [error] [client 72.247.120.220] mod_wsgi (pid=1758): Exception occurred processing WSGI script '/usr/lib/apx-hcc/hcc_project/hcc_project/wsgi.py'.<br>[Thu Aug 21 22:04:05 2014] [error] [client 72.247.120.220] Traceback (most recent call last):<br>[Thu Aug 21 22:04:05 2014] [error] [client 72.247.120.220]   File "/usr/lib/apx-hcc/.venv/lib/python2.7/site-packages/django/core/handlers/wsgi.py", line 255, in __call__<br>[Thu Aug 21 22:04:05 2014] [error] [client 72.247.120.220]     response = self.get_response(request)<br>[Thu Aug 21 22:04:05 2014] [error] [client 72.247.120.220]   File "/usr/lib/apx-hcc/.venv/lib/python2.7/site-packages/django/core/handlers/base.py", line 178, in get_response<br>[Thu Aug 21 22:04:05 2014] [error] [client 72.247.120.220]     response = self.handle_uncaught_exception(request, resolver, sys.exc_info())<br>[Thu Aug 21 22:04:05 2014] [error] [client 72.247.120.220]   File "/usr/lib/apx-hcc/.venv/lib/python2.7/site-packages/django/core/handlers/base.py", line 212, in handle_uncaught_exception<br>[Thu Aug 21 22:04:05 2014] [error] [client 72.247.120.220]     'request': request<br>[Thu Aug 21 22:04:05 2014] [error] [client 72.247.120.220]   File "/usr/lib64/python2.7/logging/__init__.py", line 1166, in error<br>[Thu Aug 21 22:04:05 2014] [error] [client 72.247.120.220]     self._log(ERROR, msg, args, **kwargs)<br>[Thu Aug 21 22:04:05 2014] [error] [client 72.247.120.220]   File "/usr/lib64/python2.7/logging/__init__.py", line 1258, in _log<br>[Thu Aug 21 22:04:05 2014] [error] [client 72.247.120.220]     self.handle(record)<br>[Thu Aug 21 22:04:05 2014] [error] [client 72.247.120.220]   File "/usr/lib64/python2.7/logging/__init__.py", line 1268, in handle<br>[Thu Aug 21 22:04:05 2014] [error] [client 72.247.120.220]     self.callHandlers(record)<br>[Thu Aug 21 22:04:05 2014] [error] [client 72.247.120.220]   File "/usr/lib64/python2.7/logging/__init__.py", line 1308, in callHandlers<br>[Thu Aug 21 22:04:05 2014] [error] [client 72.247.120.220]     hdlr.handle(record)<br>[Thu Aug 21 22:04:05 2014] [error] [client 72.247.120.220]   File "/usr/lib64/python2.7/logging/__init__.py", line 748, in handle<br>[Thu Aug 21 22:04:05 2014] [error] [client 72.247.120.220]     self.emit(record)<br>[Thu Aug 21 22:04:05 2014] [error] [client 72.247.120.220]   File "/usr/lib/apx-hcc/.venv/lib/python2.7/site-packages/django/utils/log.py", line 112, in emit<br>[Thu Aug 21 22:04:05 2014] [error] [client 72.247.120.220]     html_message = self.include_html and reporter.get_traceback_html() or None<br>[Thu Aug 21 22:04:05 2014] [error] [client 72.247.120.220]   File "/usr/lib/apx-hcc/.venv/lib/python2.7/site-packages/django/views/debug.py", line 298, in get_traceback_html<br>[Thu Aug 21 22:04:05 2014] [error] [client 72.247.120.220]     return t.render(c)<br>[Thu Aug 21 22:04:05 2014] [error] [client 72.247.120.220]   File "/usr/lib/apx-hcc/.venv/lib/python2.7/site-packages/django/template/base.py", line 140, in render<br>[Thu Aug 21 22:04:05 2014] [error] [client 72.247.120.220]     return self._render(context)<br>[Thu Aug 21 22:04:05 2014] [error] [client 72.247.120.220]   File "/usr/lib/apx-hcc/.venv/lib/python2.7/site-packages/django/template/base.py", line 134, in _render<br>[Thu Aug 21 22:04:05 2014] [error] [client 72.247.120.220]     return self.nodelist.render(context)<br>[Thu Aug 21 22:04:05 2014] [error] [client 72.247.120.220]   File "/usr/lib/apx-hcc/.venv/lib/python2.7/site-packages/django/template/base.py", line 830, in render<br>[Thu Aug 21 22:04:05 2014] [error] [client 72.247.120.220]     bit = self.render_node(node, context)<br>[Thu Aug 21 22:04:05 2014] [error] [client 72.247.120.220]   File "/usr/lib/apx-hcc/.venv/lib/python2.7/site-packages/django/template/base.py", line 844, in render_node<br>[Thu Aug 21 22:04:05 2014] [error] [client 72.247.120.220]     return node.render(context)<br>[Thu Aug 21 22:04:05 2014] [error] [client 72.247.120.220]   File "/usr/lib/apx-hcc/.venv/lib/python2.7/site-packages/django/template/defaulttags.py", line 284, in render<br>[Thu Aug 21 22:04:05 2014] [error] [client 72.247.120.220]     return nodelist.render(context)<br>[Thu Aug 21 22:04:05 2014] [error] [client 72.247.120.220]   File "/usr/lib/apx-hcc/.venv/lib/python2.7/site-packages/django/template/base.py", line 830, in render<br>[Thu Aug 21 22:04:05 2014] [error] [client 72.247.120.220]     bit = self.render_node(node, context)<br>[Thu Aug 21 22:04:05 2014] [error] [client 72.247.120.220]   File "/usr/lib/apx-hcc/.venv/lib/python2.7/site-packages/django/template/base.py", line 844, in render_node<br>[Thu Aug 21 22:04:05 2014] [error] [client 72.247.120.220]     return node.render(context)<br>[Thu Aug 21 22:04:05 2014] [error] [client 72.247.120.220]   File "/usr/lib/apx-hcc/.venv/lib/python2.7/site-packages/django/template/base.py", line 881, in render<br>[Thu Aug 21 22:04:05 2014] [error] [client 72.247.120.220]     output = self.filter_expression.resolve(context)<br>[Thu Aug 21 22:04:05 2014] [error] [client 72.247.120.220]   File "/usr/lib/apx-hcc/.venv/lib/python2.7/site-packages/django/template/base.py", line 578, in resolve<br>[Thu Aug 21 22:04:05 2014] [error] [client 72.247.120.220]     obj = self.var.resolve(context)<br>[Thu Aug 21 22:04:05 2014] [error] [client 72.247.120.220]   File "/usr/lib/apx-hcc/.venv/lib/python2.7/site-packages/django/template/base.py", line 728, in resolve<br>[Thu Aug 21 22:04:05 2014] [error] [client 72.247.120.220]     value = self._resolve_lookup(context)<br>[Thu Aug 21 22:04:05 2014] [error] [client 72.247.120.220]   File "/usr/lib/apx-hcc/.venv/lib/python2.7/site-packages/django/template/base.py", line 779, in _resolve_lookup<br>[Thu Aug 21 22:04:05 2014] [error] [client 72.247.120.220]     current = current()<br>[Thu Aug 21 22:04:05 2014] [error] [client 72.247.120.220]   File "/usr/lib/apx-hcc/.venv/lib/python2.7/site-packages/django/http/request.py", line 112, in build_absolute_uri<br>[Thu Aug 21 22:04:05 2014] [error] [client 72.247.120.220]     self.get_host(), self.path)<br>[Thu Aug 21 22:04:05 2014] [error] [client 72.247.120.220]   File "/usr/lib/apx-hcc/.venv/lib/python2.7/site-packages/django/http/request.py", line 72, in get_host<br>[Thu Aug 21 22:04:05 2014] [error] [client 72.247.120.220]     "Invalid HTTP_HOST header (you may need to set ALLOWED_HOSTS): %s" % host)<br>[Thu Aug 21 22:04:05 2014] [error] [client 72.247.120.220] SuspiciousOperation: Invalid HTTP_HOST header (you may need to set ALLOWED_HOSTS): all-s3-us-ic2.digitalhub.com.akadns.net<br>[Thu Aug 21 22:04:19 2014] [error] ('production.hcc', 1408683859, {'sys_module': 'base', 'source': 'django.request', 'host': '64.120.6.122', 'session': None, 'user': u'', 'time': '1408709059739', 'datestamp': '2014-08-22T05:04:19.739172', 'level': 'ERROR', 'sys_host': 'ip-10-172-93-72', 'msecs': 738.5549545288086})<br>[Thu Aug 21 22:04:19 2014] [error] [client 204.2.160.183] mod_wsgi (pid=1758): Exception occurred processing WSGI script '/usr/lib/apx-hcc/hcc_project/hcc_project/wsgi.py'.<br>[Thu Aug 21 22:04:19 2014] [error] [client 204.2.160.183] Traceback (most recent call last):<br>[Thu Aug 21 22:04:19 2014] [error] [client 204.2.160.183]   File "/usr/lib/apx-hcc/.venv/lib/python2.7/site-packages/django/core/handlers/wsgi.py", line 255, in __call__<br>[Thu Aug 21 22:04:19 2014] [error] [client 204.2.160.183]     response = self.get_response(request)<br>[Thu Aug 21 22:04:19 2014] [error] [client 204.2.160.183]   File "/usr/lib/apx-hcc/.venv/lib/python2.7/site-packages/django/core/handlers/base.py", line 178, in get_response<br>[Thu Aug 21 22:04:19 2014] [error] [client 204.2.160.183]     response = self.handle_uncaught_exception(request, resolver, sys.exc_info())<br>[Thu Aug 21 22:04:19 2014] [error] [client 204.2.160.183]   File "/usr/lib/apx-hcc/.venv/lib/python2.7/site-packages/django/core/handlers/base.py", line 212, in handle_uncaught_exception<br>[Thu Aug 21 22:04:19 2014] [error] [client 204.2.160.183]     'request': request<br>[Thu Aug 21 22:04:19 2014] [error] [client 204.2.160.183]   File "/usr/lib64/python2.7/logging/__init__.py", line 1166, in error<br>[Thu Aug 21 22:04:19 2014] [error] [client 204.2.160.183]     self._log(ERROR, msg, args, **kwargs)<br>[Thu Aug 21 22:04:19 2014] [error] [client 204.2.160.183]   File "/usr/lib64/python2.7/logging/__init__.py", line 1258, in _log<br>[Thu Aug 21 22:04:19 2014] [error] [client 204.2.160.183]     self.handle(record)<br>[Thu Aug 21 22:04:19 2014] [error] [client 204.2.160.183]   File "/usr/lib64/python2.7/logging/__init__.py", line 1268, in handle<br>[Thu Aug 21 22:04:19 2014] [error] [client 204.2.160.183]     self.callHandlers(record)<br>[Thu Aug 21 22:04:19 2014] [error] [client 204.2.160.183]   File "/usr/lib64/python2.7/logging/__init__.py", line 1308, in callHandlers<br>[Thu Aug 21 22:04:19 2014] [error] [client 204.2.160.183]     hdlr.handle(record)<br>[Thu Aug 21 22:04:19 2014] [error] [client 204.2.160.183]   File "/usr/lib64/python2.7/logging/__init__.py", line 748, in handle<br>[Thu Aug 21 22:04:19 2014] [error] [client 204.2.160.183]     self.emit(record)<br>[Thu Aug 21 22:04:19 2014] [error] [client 204.2.160.183]   File "/usr/lib/apx-hcc/.venv/lib/python2.7/site-packages/django/utils/log.py", line 112, in emit<br>[Thu Aug 21 22:04:19 2014] [error] [client 204.2.160.183]     html_message = self.include_html and reporter.get_traceback_html() or None<br>[Thu Aug 21 22:04:19 2014] [error] [client 204.2.160.183]   File "/usr/lib/apx-hcc/.venv/lib/python2.7/site-packages/django/views/debug.py", line 298, in get_traceback_html<br>[Thu Aug 21 22:04:19 2014] [error] [client 204.2.160.183]     return t.render(c)<br>[Thu Aug 21 22:04:19 2014] [error] [client 204.2.160.183]   File "/usr/lib/apx-hcc/.venv/lib/python2.7/site-packages/django/template/base.py", line 140, in render<br>[Thu Aug 21 22:04:19 2014] [error] [client 204.2.160.183]     return self._render(context)<br>[Thu Aug 21 22:04:19 2014] [error] [client 204.2.160.183]   File "/usr/lib/apx-hcc/.venv/lib/python2.7/site-packages/django/template/base.py", line 134, in _render<br>[Thu Aug 21 22:04:19 2014] [error] [client 204.2.160.183]     return self.nodelist.render(context)<br>[Thu Aug 21 22:04:19 2014] [error] [client 204.2.160.183]   File "/usr/lib/apx-hcc/.venv/lib/python2.7/site-packages/django/template/base.py", line 830, in render<br>[Thu Aug 21 22:04:19 2014] [error] [client 204.2.160.183]     bit = self.render_node(node, context)<br>[Thu Aug 21 22:04:19 2014] [error] [client 204.2.160.183]   File "/usr/lib/apx-hcc/.venv/lib/python2.7/site-packages/django/template/base.py", line 844, in render_node<br>[Thu Aug 21 22:04:19 2014] [error] [client 204.2.160.183]     return node.render(context)<br>[Thu Aug 21 22:04:19 2014] [error] [client 204.2.160.183]   File "/usr/lib/apx-hcc/.venv/lib/python2.7/site-packages/django/template/defaulttags.py", line 284, in render<br>[Thu Aug 21 22:04:19 2014] [error] [client 204.2.160.183]     return nodelist.render(context)<br>[Thu Aug 21 22:04:19 2014] [error] [client 204.2.160.183]   File "/usr/lib/apx-hcc/.venv/lib/python2.7/site-packages/django/template/base.py", line 830, in render<br>[Thu Aug 21 22:04:19 2014] [error] [client 204.2.160.183]     bit = self.render_node(node, context)<br>[Thu Aug 21 22:04:19 2014] [error] [client 204.2.160.183]   File "/usr/lib/apx-hcc/.venv/lib/python2.7/site-packages/django/template/base.py", line 844, in render_node<br>[Thu Aug 21 22:04:19 2014] [error] [client 204.2.160.183]     return node.render(context)<br>[Thu Aug 21 22:04:19 2014] [error] [client 204.2.160.183]   File "/usr/lib/apx-hcc/.venv/lib/python2.7/site-packages/django/template/base.py", line 881, in render<br>[Thu Aug 21 22:04:19 2014] [error] [client 204.2.160.183]     output = self.filter_expression.resolve(context)<br>[Thu Aug 21 22:04:19 2014] [error] [client 204.2.160.183]   File "/usr/lib/apx-hcc/.venv/lib/python2.7/site-packages/django/template/base.py", line 578, in resolve<br>[Thu Aug 21 22:04:19 2014] [error] [client 204.2.160.183]     obj = self.var.resolve(context)<br>[Thu Aug 21 22:04:19 2014] [error] [client 204.2.160.183]   File "/usr/lib/apx-hcc/.venv/lib/python2.7/site-packages/django/template/base.py", line 728, in resolve<br>[Thu Aug 21 22:04:19 2014] [error] [client 204.2.160.183]     value = self._resolve_lookup(context)<br>[Thu Aug 21 22:04:19 2014] [error] [client 204.2.160.183]   File "/usr/lib/apx-hcc/.venv/lib/python2.7/site-packages/django/template/base.py", line 779, in _resolve_lookup<br>[Thu Aug 21 22:04:19 2014] [error] [client 204.2.160.183]     current = current()<br>[Thu Aug 21 22:04:19 2014] [error] [client 204.2.160.183]   File "/usr/lib/apx-hcc/.venv/lib/python2.7/site-packages/django/http/request.py", line 112, in build_absolute_uri<br>[Thu Aug 21 22:04:19 2014] [error] [client 204.2.160.183]     self.get_host(), self.path)<br>[Thu Aug 21 22:04:19 2014] [error] [client 204.2.160.183]   File "/usr/lib/apx-hcc/.venv/lib/python2.7/site-packages/django/http/request.py", line 72, in get_host<br>[Thu Aug 21 22:04:19 2014] [error] [client 204.2.160.183]     "Invalid HTTP_HOST header (you may need to set ALLOWED_HOSTS): %s" % host)<br>[Thu Aug 21 22:04:19 2014] [error] [client 204.2.160.183] SuspiciousOperation: Invalid HTTP_HOST header (you may need to set ALLOWED_HOSTS): all-s3-us-ic2.digitalhub.com.akadns.net<br>[Thu Aug 21 22:04:25 2014] [error] ('production.hcc', 1408683865, {'sys_module': 'base', 'source': 'django.request', 'host': '72.46.140.186', 'session': None, 'user': u'', 'time': '1408709065232', 'datestamp': '2014-08-22T05:04:25.232529', 'level': 'ERROR', 'sys_host': 'ip-10-172-93-72', 'msecs': 231.9190502166748})<br>[Thu Aug 21 22:04:25 2014] [error] [client 198.63.231.28] mod_wsgi (pid=1758): Exception occurred processing WSGI script '/usr/lib/apx-hcc/hcc_project/hcc_project/wsgi.py'.<br>[Thu Aug 21 22:04:25 2014] [error] [client 198.63.231.28] Traceback (most recent call last):<br>[Thu Aug 21 22:04:25 2014] [error] [client 198.63.231.28]   File "/usr/lib/apx-hcc/.venv/lib/python2.7/site-packages/django/core/handlers/wsgi.py", line 255, in __call__<br>[Thu Aug 21 22:04:25 2014] [error] [client 198.63.231.28]     response = self.get_response(request)<br>[Thu Aug 21 22:04:25 2014] [error] [client 198.63.231.28]   File "/usr/lib/apx-hcc/.venv/lib/python2.7/site-packages/django/core/handlers/base.py", line 178, in get_response<br>[Thu Aug 21 22:04:25 2014] [error] [client 198.63.231.28]     response = self.handle_uncaught_exception(request, resolver, sys.exc_info())<br>[Thu Aug 21 22:04:25 2014] [error] [client 198.63.231.28]   File "/usr/lib/apx-hcc/.venv/lib/python2.7/site-packages/django/core/handlers/base.py", line 212, in handle_uncaught_exception<br>[Thu Aug 21 22:04:25 2014] [error] [client 198.63.231.28]     'request': request<br>[Thu Aug 21 22:04:25 2014] [error] [client 198.63.231.28]   File "/usr/lib64/python2.7/logging/__init__.py", line 1166, in error<br>[Thu Aug 21 22:04:25 2014] [error] [client 198.63.231.28]     self._log(ERROR, msg, args, **kwargs)<br>[Thu Aug 21 22:04:25 2014] [error] [client 198.63.231.28]   File "/usr/lib64/python2.7/logging/__init__.py", line 1258, in _log<br>[Thu Aug 21 22:04:25 2014] [error] [client 198.63.231.28]     self.handle(record)<br>[Thu Aug 21 22:04:25 2014] [error] [client 198.63.231.28]   File "/usr/lib64/python2.7/logging/__init__.py", line 1268, in handle<br>[Thu Aug 21 22:04:25 2014] [error] [client 198.63.231.28]     self.callHandlers(record)<br>[Thu Aug 21 22:04:25 2014] [error] [client 198.63.231.28]   File "/usr/lib64/python2.7/logging/__init__.py", line 1308, in callHandlers<br>[Thu Aug 21 22:04:25 2014] [error] [client 198.63.231.28]     hdlr.handle(record)<br>[Thu Aug 21 22:04:25 2014] [error] [client 198.63.231.28]   File "/usr/lib64/python2.7/logging/__init__.py", line 748, in handle<br>[Thu Aug 21 22:04:25 2014] [error] [client 198.63.231.28]     self.emit(record)<br>[Thu Aug 21 22:04:25 2014] [error] [client 198.63.231.28]   File "/usr/lib/apx-hcc/.venv/lib/python2.7/site-packages/django/utils/log.py", line 112, in emit<br>[Thu Aug 21 22:04:25 2014] [error] [client 198.63.231.28]     html_message = self.include_html and reporter.get_traceback_html() or None<br>[Thu Aug 21 22:04:25 2014] [error] [client 198.63.231.28]   File "/usr/lib/apx-hcc/.venv/lib/python2.7/site-packages/django/views/debug.py", line 298, in get_traceback_html<br>[Thu Aug 21 22:04:25 2014] [error] [client 198.63.231.28]     return t.render(c)<br>[Thu Aug 21 22:04:25 2014] [error] [client 198.63.231.28]   File "/usr/lib/apx-hcc/.venv/lib/python2.7/site-packages/django/template/base.py", line 140, in render<br>[Thu Aug 21 22:04:25 2014] [error] [client 198.63.231.28]     return self._render(context)<br>[Thu Aug 21 22:04:25 2014] [error] [client 198.63.231.28]   File "/usr/lib/apx-hcc/.venv/lib/python2.7/site-packages/django/template/base.py", line 134, in _render<br>[Thu Aug 21 22:04:25 2014] [error] [client 198.63.231.28]     return self.nodelist.render(context)<br>[Thu Aug 21 22:04:25 2014] [error] [client 198.63.231.28]   File "/usr/lib/apx-hcc/.venv/lib/python2.7/site-packages/django/template/base.py", line 830, in render<br>[Thu Aug 21 22:04:25 2014] [error] [client 198.63.231.28]     bit = self.render_node(node, context)<br>[Thu Aug 21 22:04:25 2014] [error] [client 198.63.231.28]   File "/usr/lib/apx-hcc/.venv/lib/python2.7/site-packages/django/template/base.py", line 844, in render_node<br>[Thu Aug 21 22:04:25 2014] [error] [client 198.63.231.28]     return node.render(context)<br>[Thu Aug 21 22:04:25 2014] [error] [client 198.63.231.28]   File "/usr/lib/apx-hcc/.venv/lib/python2.7/site-packages/django/template/defaulttags.py", line 284, in render<br>[Thu Aug 21 22:04:25 2014] [error] [client 198.63.231.28]     return nodelist.render(context)<br>[Thu Aug 21 22:04:25 2014] [error] [client 198.63.231.28]   File "/usr/lib/apx-hcc/.venv/lib/python2.7/site-packages/django/template/base.py", line 830, in render<br>[Thu Aug 21 22:04:25 2014] [error] [client 198.63.231.28]     bit = self.render_node(node, context)<br>[Thu Aug 21 22:04:25 2014] [error] [client 198.63.231.28]   File "/usr/lib/apx-hcc/.venv/lib/python2.7/site-packages/django/template/base.py", line 844, in render_node<br>[Thu Aug 21 22:04:25 2014] [error] [client 198.63.231.28]     return node.render(context)<br>[Thu Aug 21 22:04:25 2014] [error] [client 198.63.231.28]   File "/usr/lib/apx-hcc/.venv/lib/python2.7/site-packages/django/template/base.py", line 881, in render<br>[Thu Aug 21 22:04:25 2014] [error] [client 198.63.231.28]     output = self.filter_expression.resolve(context)<br>[Thu Aug 21 22:04:25 2014] [error] [client 198.63.231.28]   File "/usr/lib/apx-hcc/.venv/lib/python2.7/site-packages/django/template/base.py", line 578, in resolve<br>[Thu Aug 21 22:04:25 2014] [error] [client 198.63.231.28]     obj = self.var.resolve(context)<br>[Thu Aug 21 22:04:25 2014] [error] [client 198.63.231.28]   File "/usr/lib/apx-hcc/.venv/lib/python2.7/site-packages/django/template/base.py", line 728, in resolve<br>[Thu Aug 21 22:04:25 2014] [error] [client 198.63.231.28]     value = self._resolve_lookup(context)<br>[Thu Aug 21 22:04:25 2014] [error] [client 198.63.231.28]   File "/usr/lib/apx-hcc/.venv/lib/python2.7/site-packages/django/template/base.py", line 779, in _resolve_lookup<br>[Thu Aug 21 22:04:25 2014] [error] [client 198.63.231.28]     current = current()<br>[Thu Aug 21 22:04:25 2014] [error] [client 198.63.231.28]   File "/usr/lib/apx-hcc/.venv/lib/python2.7/site-packages/django/http/request.py", line 112, in build_absolute_uri<br>[Thu Aug 21 22:04:25 2014] [error] [client 198.63.231.28]     self.get_host(), self.path)<br>[Thu Aug 21 22:04:25 2014] [error] [client 198.63.231.28]   File "/usr/lib/apx-hcc/.venv/lib/python2.7/site-packages/django/http/request.py", line 72, in get_host<br>[Thu Aug 21 22:04:25 2014] [error] [client 198.63.231.28]     "Invalid HTTP_HOST header (you may need to set ALLOWED_HOSTS): %s" % host)<br>[Thu Aug 21 22:04:25 2014] [error] [client 198.63.231.28] SuspiciousOperation: Invalid HTTP_HOST header (you may need to set ALLOWED_HOSTS): all-s3-us-ic2.digitalhub.com.akadns.net<br>[Thu Aug 21 22:04:35 2014] [error] ('production.hcc', 1408683875, {'sys_module': 'base', 'source': 'django.request', 'host': '64.120.6.122', 'session': None, 'user': u'', 'time': '1408709075432', 'datestamp': '2014-08-22T05:04:35.432540', 'level': 'ERROR', 'sys_host': 'ip-10-172-93-72', 'msecs': 431.8890571594238})<br>[Thu Aug 21 22:04:35 2014] [error] [client 72.247.120.220] mod_wsgi (pid=1758): Exception occurred processing WSGI script '/usr/lib/apx-hcc/hcc_project/hcc_project/wsgi.py'.<br>[Thu Aug 21 22:04:35 2014] [error] [client 72.247.120.220] Traceback (most recent call last):<br>[Thu Aug 21 22:04:35 2014] [error] [client 72.247.120.220]   File "/usr/lib/apx-hcc/.venv/lib/python2.7/site-packages/django/core/handlers/wsgi.py", line 255, in __call__<br>[Thu Aug 21 22:04:35 2014] [error] [client 72.247.120.220]     response = self.get_response(request)<br>[Thu Aug 21 22:04:35 2014] [error] [client 72.247.120.220]   File "/usr/lib/apx-hcc/.venv/lib/python2.7/site-packages/django/core/handlers/base.py", line 178, in get_response<br>[Thu Aug 21 22:04:35 2014] [error] [client 72.247.120.220]     response = self.handle_uncaught_exception(request, resolver, sys.exc_info())<br>[Thu Aug 21 22:04:35 2014] [error] [client 72.247.120.220]   File "/usr/lib/apx-hcc/.venv/lib/python2.7/site-packages/django/core/handlers/base.py", line 212, in handle_uncaught_exception<br>[Thu Aug 21 22:04:35 2014] [error] [client 72.247.120.220]     'request': request<br>[Thu Aug 21 22:04:35 2014] [error] [client 72.247.120.220]   File "/usr/lib64/python2.7/logging/__init__.py", line 1166, in error<br>[Thu Aug 21 22:04:35 2014] [error] [client 72.247.120.220]     self._log(ERROR, msg, args, **kwargs)<br>[Thu Aug 21 22:04:35 2014] [error] [client 72.247.120.220]   File "/usr/lib64/python2.7/logging/__init__.py", line 1258, in _log<br>[Thu Aug 21 22:04:35 2014] [error] [client 72.247.120.220]     self.handle(record)<br>[Thu Aug 21 22:04:35 2014] [error] [client 72.247.120.220]   File "/usr/lib64/python2.7/logging/__init__.py", line 1268, in handle<br>[Thu Aug 21 22:04:35 2014] [error] [client 72.247.120.220]     self.callHandlers(record)<br>[Thu Aug 21 22:04:35 2014] [error] [client 72.247.120.220]   File "/usr/lib64/python2.7/logging/__init__.py", line 1308, in callHandlers<br>[Thu Aug 21 22:04:35 2014] [error] [client 72.247.120.220]     hdlr.handle(record)<br>[Thu Aug 21 22:04:35 2014] [error] [client 72.247.120.220]   File "/usr/lib64/python2.7/logging/__init__.py", line 748, in handle<br>[Thu Aug 21 22:04:35 2014] [error] [client 72.247.120.220]     self.emit(record)<br>[Thu Aug 21 22:04:35 2014] [error] [client 72.247.120.220]   File "/usr/lib/apx-hcc/.venv/lib/python2.7/site-packages/django/utils/log.py", line 112, in emit<br>[Thu Aug 21 22:04:35 2014] [error] [client 72.247.120.220]     html_message = self.include_html and reporter.get_traceback_html() or None<br>[Thu Aug 21 22:04:35 2014] [error] [client 72.247.120.220]   File "/usr/lib/apx-hcc/.venv/lib/python2.7/site-packages/django/views/debug.py", line 298, in get_traceback_html<br>[Thu Aug 21 22:04:35 2014] [error] [client 72.247.120.220]     return t.render(c)<br>[Thu Aug 21 22:04:35 2014] [error] [client 72.247.120.220]   File "/usr/lib/apx-hcc/.venv/lib/python2.7/site-packages/django/template/base.py", line 140, in render<br>[Thu Aug 21 22:04:35 2014] [error] [client 72.247.120.220]     return self._render(context)<br>[Thu Aug 21 22:04:35 2014] [error] [client 72.247.120.220]   File "/usr/lib/apx-hcc/.venv/lib/python2.7/site-packages/django/template/base.py", line 134, in _render<br>[Thu Aug 21 22:04:35 2014] [error] [client 72.247.120.220]     return self.nodelist.render(context)<br>[Thu Aug 21 22:04:35 2014] [error] [client 72.247.120.220]   File "/usr/lib/apx-hcc/.venv/lib/python2.7/site-packages/django/template/base.py", line 830, in render<br>[Thu Aug 21 22:04:35 2014] [error] [client 72.247.120.220]     bit = self.render_node(node, context)<br>[Thu Aug 21 22:04:35 2014] [error] [client 72.247.120.220]   File "/usr/lib/apx-hcc/.venv/lib/python2.7/site-packages/django/template/base.py", line 844, in render_node<br>[Thu Aug 21 22:04:35 2014] [error] [client 72.247.120.220]     return node.render(context)<br>[Thu Aug 21 22:04:35 2014] [error] [client 72.247.120.220]   File "/usr/lib/apx-hcc/.venv/lib/python2.7/site-packages/django/template/defaulttags.py", line 284, in render<br>[Thu Aug 21 22:04:35 2014] [error] [client 72.247.120.220]     return nodelist.render(context)<br>[Thu Aug 21 22:04:35 2014] [error] [client 72.247.120.220]   File "/usr/lib/apx-hcc/.venv/lib/python2.7/site-packages/django/template/base.py", line 830, in render<br>[Thu Aug 21 22:04:35 2014] [error] [client 72.247.120.220]     bit = self.render_node(node, context)<br>[Thu Aug 21 22:04:35 2014] [error] [client 72.247.120.220]   File "/usr/lib/apx-hcc/.venv/lib/python2.7/site-packages/django/template/base.py", line 844, in render_node<br>[Thu Aug 21 22:04:35 2014] [error] [client 72.247.120.220]     return node.render(context)<br>[Thu Aug 21 22:04:35 2014] [error] [client 72.247.120.220]   File "/usr/lib/apx-hcc/.venv/lib/python2.7/site-packages/django/template/base.py", line 881, in render<br>[Thu Aug 21 22:04:35 2014] [error] [client 72.247.120.220]     output = self.filter_expression.resolve(context)<br>[Thu Aug 21 22:04:35 2014] [error] [client 72.247.120.220]   File "/usr/lib/apx-hcc/.venv/lib/python2.7/site-packages/django/template/base.py", line 578, in resolve<br>[Thu Aug 21 22:04:35 2014] [error] [client 72.247.120.220]     obj = self.var.resolve(context)<br>[Thu Aug 21 22:04:35 2014] [error] [client 72.247.120.220]   File "/usr/lib/apx-hcc/.venv/lib/python2.7/site-packages/django/template/base.py", line 728, in resolve<br>[Thu Aug 21 22:04:35 2014] [error] [client 72.247.120.220]     value = self._resolve_lookup(context)<br>[Thu Aug 21 22:04:35 2014] [error] [client 72.247.120.220]   File "/usr/lib/apx-hcc/.venv/lib/python2.7/site-packages/django/template/base.py", line 779, in _resolve_lookup<br>[Thu Aug 21 22:04:35 2014] [error] [client 72.247.120.220]     current = current()<br>[Thu Aug 21 22:04:35 2014] [error] [client 72.247.120.220]   File "/usr/lib/apx-hcc/.venv/lib/python2.7/site-packages/django/http/request.py", line 112, in build_absolute_uri<br>[Thu Aug 21 22:04:35 2014] [error] [client 72.247.120.220]     self.get_host(), self.path)<br>[Thu Aug 21 22:04:35 2014] [error] [client 72.247.120.220]   File "/usr/lib/apx-hcc/.venv/lib/python2.7/site-packages/django/http/request.py", line 72, in get_host<br>[Thu Aug 21 22:04:35 2014] [error] [client 72.247.120.220]     "Invalid HTTP_HOST header (you may need to set ALLOWED_HOSTS): %s" % host)<br>[Thu Aug 21 22:04:35 2014] [error] [client 72.247.120.220] SuspiciousOperation: Invalid HTTP_HOST header (you may need to set ALLOWED_HOSTS): all-s3-us-ic2.digitalhub.com.akadns.net<br>[Thu Aug 21 22:04:38 2014] [error] ('production.hcc', 1408683878, {'sys_module': 'base', 'source': 'django.request', 'host': '72.46.140.186', 'session': None, 'user': u'', 'time': '1408709078715', 'datestamp': '2014-08-22T05:04:38.715819', 'level': 'ERROR', 'sys_host': 'ip-10-172-93-72', 'msecs': 715.1980400085449})<br>[Thu Aug 21 22:04:38 2014] [error] [client 205.185.205.132] mod_wsgi (pid=1758): Exception occurred processing WSGI script '/usr/lib/apx-hcc/hcc_project/hcc_project/wsgi.py'.<br>[Thu Aug 21 22:04:38 2014] [error] [client 205.185.205.132] Traceback (most recent call last):<br>[Thu Aug 21 22:04:38 2014] [error] [client 205.185.205.132]   File "/usr/lib/apx-hcc/.venv/lib/python2.7/site-packages/django/core/handlers/wsgi.py", line 255, in __call__<br>[Thu Aug 21 22:04:38 2014] [error] [client 205.185.205.132]     response = self.get_response(request)<br>[Thu Aug 21 22:04:38 2014] [error] [client 205.185.205.132]   File "/usr/lib/apx-hcc/.venv/lib/python2.7/site-packages/django/core/handlers/base.py", line 178, in get_response<br>[Thu Aug 21 22:04:38 2014] [error] [client 205.185.205.132]     response = self.handle_uncaught_exception(request, resolver, sys.exc_info())<br>[Thu Aug 21 22:04:38 2014] [error] [client 205.185.205.132]   File "/usr/lib/apx-hcc/.venv/lib/python2.7/site-packages/django/core/handlers/base.py", line 212, in handle_uncaught_exception<br>[Thu Aug 21 22:04:38 2014] [error] [client 205.185.205.132]     'request': request<br>[Thu Aug 21 22:04:38 2014] [error] [client 205.185.205.132]   File "/usr/lib64/python2.7/logging/__init__.py", line 1166, in error<br>[Thu Aug 21 22:04:38 2014] [error] [client 205.185.205.132]     self._log(ERROR, msg, args, **kwargs)<br>[Thu Aug 21 22:04:38 2014] [error] [client 205.185.205.132]   File "/usr/lib64/python2.7/logging/__init__.py", line 1258, in _log<br>[Thu Aug 21 22:04:38 2014] [error] [client 205.185.205.132]     self.handle(record)<br>[Thu Aug 21 22:04:38 2014] [error] [client 205.185.205.132]   File "/usr/lib64/python2.7/logging/__init__.py", line 1268, in handle<br>[Thu Aug 21 22:04:38 2014] [error] [client 205.185.205.132]     self.callHandlers(record)<br>[Thu Aug 21 22:04:38 2014] [error] [client 205.185.205.132]   File "/usr/lib64/python2.7/logging/__init__.py", line 1308, in callHandlers<br>[Thu Aug 21 22:04:38 2014] [error] [client 205.185.205.132]     hdlr.handle(record)<br>[Thu Aug 21 22:04:38 2014] [error] [client 205.185.205.132]   File "/usr/lib64/python2.7/logging/__init__.py", line 748, in handle<br>[Thu Aug 21 22:04:38 2014] [error] [client 205.185.205.132]     self.emit(record)<br>[Thu Aug 21 22:04:38 2014] [error] [client 205.185.205.132]   File "/usr/lib/apx-hcc/.venv/lib/python2.7/site-packages/django/utils/log.py", line 112, in emit<br>[Thu Aug 21 22:04:38 2014] [error] [client 205.185.205.132]     html_message = self.include_html and reporter.get_traceback_html() or None<br>[Thu Aug 21 22:04:38 2014] [error] [client 205.185.205.132]   File "/usr/lib/apx-hcc/.venv/lib/python2.7/site-packages/django/views/debug.py", line 298, in get_traceback_html<br>[Thu Aug 21 22:04:38 2014] [error] [client 205.185.205.132]     return t.render(c)<br>[Thu Aug 21 22:04:38 2014] [error] [client 205.185.205.132]   File "/usr/lib/apx-hcc/.venv/lib/python2.7/site-packages/django/template/base.py", line 140, in render<br>[Thu Aug 21 22:04:38 2014] [error] [client 205.185.205.132]     return self._render(context)<br>[Thu Aug 21 22:04:38 2014] [error] [client 205.185.205.132]   File "/usr/lib/apx-hcc/.venv/lib/python2.7/site-packages/django/template/base.py", line 134, in _render<br>[Thu Aug 21 22:04:38 2014] [error] [client 205.185.205.132]     return self.nodelist.render(context)<br>[Thu Aug 21 22:04:38 2014] [error] [client 205.185.205.132]   File "/usr/lib/apx-hcc/.venv/lib/python2.7/site-packages/django/template/base.py", line 830, in render<br>[Thu Aug 21 22:04:38 2014] [error] [client 205.185.205.132]     bit = self.render_node(node, context)<br>[Thu Aug 21 22:04:38 2014] [error] [client 205.185.205.132]   File "/usr/lib/apx-hcc/.venv/lib/python2.7/site-packages/django/template/base.py", line 844, in render_node<br>[Thu Aug 21 22:04:38 2014] [error] [client 205.185.205.132]     return node.render(context)<br>[Thu Aug 21 22:04:38 2014] [error] [client 205.185.205.132]   File "/usr/lib/apx-hcc/.venv/lib/python2.7/site-packages/django/template/defaulttags.py", line 284, in render<br>[Thu Aug 21 22:04:38 2014] [error] [client 205.185.205.132]     return nodelist.render(context)<br>[Thu Aug 21 22:04:38 2014] [error] [client 205.185.205.132]   File "/usr/lib/apx-hcc/.venv/lib/python2.7/site-packages/django/template/base.py", line 830, in render<br>[Thu Aug 21 22:04:38 2014] [error] [client 205.185.205.132]     bit = self.render_node(node, context)<br>[Thu Aug 21 22:04:38 2014] [error] [client 205.185.205.132]   File "/usr/lib/apx-hcc/.venv/lib/python2.7/site-packages/django/template/base.py", line 844, in render_node<br>[Thu Aug 21 22:04:38 2014] [error] [client 205.185.205.132]     return node.render(context)<br>[Thu Aug 21 22:04:38 2014] [error] [client 205.185.205.132]   File "/usr/lib/apx-hcc/.venv/lib/python2.7/site-packages/django/template/base.py", line 881, in render<br>[Thu Aug 21 22:04:38 2014] [error] [client 205.185.205.132]     output = self.filter_expression.resolve(context)<br>[Thu Aug 21 22:04:38 2014] [error] [client 205.185.205.132]   File "/usr/lib/apx-hcc/.venv/lib/python2.7/site-packages/django/template/base.py", line 578, in resolve<br>[Thu Aug 21 22:04:38 2014] [error] [client 205.185.205.132]     obj = self.var.resolve(context)<br>[Thu Aug 21 22:04:38 2014] [error] [client 205.185.205.132]   File "/usr/lib/apx-hcc/.venv/lib/python2.7/site-packages/django/template/base.py", line 728, in resolve<br>[Thu Aug 21 22:04:38 2014] [error] [client 205.185.205.132]     value = self._resolve_lookup(context)<br>[Thu Aug 21 22:04:38 2014] [error] [client 205.185.205.132]   File "/usr/lib/apx-hcc/.venv/lib/python2.7/site-packages/django/template/base.py", line 779, in _resolve_lookup<br>[Thu Aug 21 22:04:38 2014] [error] [client 205.185.205.132]     current = current()<br>[Thu Aug 21 22:04:38 2014] [error] [client 205.185.205.132]   File "/usr/lib/apx-hcc/.venv/lib/python2.7/site-packages/django/http/request.py", line 112, in build_absolute_uri<br>[Thu Aug 21 22:04:38 2014] [error] [client 205.185.205.132]     self.get_host(), self.path)<br>[Thu Aug 21 22:04:38 2014] [error] [client 205.185.205.132]   File "/usr/lib/apx-hcc/.venv/lib/python2.7/site-packages/django/http/request.py", line 72, in get_host<br>[Thu Aug 21 22:04:38 2014] [error] [client 205.185.205.132]     "Invalid HTTP_HOST header (you may need to set ALLOWED_HOSTS): %s" % host)<br>[Thu Aug 21 22:04:38 2014] [error] [client 205.185.205.132] SuspiciousOperation: Invalid HTTP_HOST header (you may need to set ALLOWED_HOSTS): all-s3-us-ic2.digitalhub.com.akadns.net<br>[Thu Aug 21 22:04:39 2014] [error] ('production.hcc', 1408683879, {'sys_module': 'base', 'source': 'django.request', 'host': '64.120.6.122', 'session': None, 'user': u'', 'time': '1408709079590', 'datestamp': '2014-08-22T05:04:39.590400', 'level': 'ERROR', 'sys_host': 'ip-10-172-93-72', 'msecs': 589.8029804229736})<br>[Thu Aug 21 22:04:39 2014] [error] [client 77.67.85.53] mod_wsgi (pid=1758): Exception occurred processing WSGI script '/usr/lib/apx-hcc/hcc_project/hcc_project/wsgi.py'.<br>[Thu Aug 21 22:04:39 2014] [error] [client 77.67.85.53] Traceback (most recent call last):<br>[Thu Aug 21 22:04:39 2014] [error] [client 77.67.85.53]   File "/usr/lib/apx-hcc/.venv/lib/python2.7/site-packages/django/core/handlers/wsgi.py", line 255, in __call__<br>[Thu Aug 21 22:04:39 2014] [error] [client 77.67.85.53]     response = self.get_response(request)<br>[Thu Aug 21 22:04:39 2014] [error] [client 77.67.85.53]   File "/usr/lib/apx-hcc/.venv/lib/python2.7/site-packages/django/core/handlers/base.py", line 178, in get_response<br>[Thu Aug 21 22:04:39 2014] [error] [client 77.67.85.53]     response = self.handle_uncaught_exception(request, resolver, sys.exc_info())<br>[Thu Aug 21 22:04:39 2014] [error] [client 77.67.85.53]   File "/usr/lib/apx-hcc/.venv/lib/python2.7/site-packages/django/core/handlers/base.py", line 212, in handle_uncaught_exception<br>[Thu Aug 21 22:04:39 2014] [error] [client 77.67.85.53]     'request': request<br>[Thu Aug 21 22:04:39 2014] [error] [client 77.67.85.53]   File "/usr/lib64/python2.7/logging/__init__.py", line 1166, in error<br>[Thu Aug 21 22:04:39 2014] [error] [client 77.67.85.53]     self._log(ERROR, msg, args, **kwargs)<br>[Thu Aug 21 22:04:39 2014] [error] [client 77.67.85.53]   File "/usr/lib64/python2.7/logging/__init__.py", line 1258, in _log<br>[Thu Aug 21 22:04:39 2014] [error] [client 77.67.85.53]     self.handle(record)<br>[Thu Aug 21 22:04:39 2014] [error] [client 77.67.85.53]   File "/usr/lib64/python2.7/logging/__init__.py", line 1268, in handle<br>[Thu Aug 21 22:04:39 2014] [error] [client 77.67.85.53]     self.callHandlers(record)<br>[Thu Aug 21 22:04:39 2014] [error] [client 77.67.85.53]   File "/usr/lib64/python2.7/logging/__init__.py", line 1308, in callHandlers<br>[Thu Aug 21 22:04:39 2014] [error] [client 77.67.85.53]     hdlr.handle(record)<br>[Thu Aug 21 22:04:39 2014] [error] [client 77.67.85.53]   File "/usr/lib64/python2.7/logging/__init__.py", line 748, in handle<br>[Thu Aug 21 22:04:39 2014] [error] [client 77.67.85.53]     self.emit(record)<br>[Thu Aug 21 22:04:39 2014] [error] [client 77.67.85.53]   File "/usr/lib/apx-hcc/.venv/lib/python2.7/site-packages/django/utils/log.py", line 112, in emit<br>[Thu Aug 21 22:04:39 2014] [error] [client 77.67.85.53]     html_message = self.include_html and reporter.get_traceback_html() or None<br>[Thu Aug 21 22:04:39 2014] [error] [client 77.67.85.53]   File "/usr/lib/apx-hcc/.venv/lib/python2.7/site-packages/django/views/debug.py", line 298, in get_traceback_html<br>[Thu Aug 21 22:04:39 2014] [error] [client 77.67.85.53]     return t.render(c)<br>[Thu Aug 21 22:04:39 2014] [error] [client 77.67.85.53]   File "/usr/lib/apx-hcc/.venv/lib/python2.7/site-packages/django/template/base.py", line 140, in render<br>[Thu Aug 21 22:04:39 2014] [error] [client 77.67.85.53]     return self._render(context)<br>[Thu Aug 21 22:04:39 2014] [error] [client 77.67.85.53]   File "/usr/lib/apx-hcc/.venv/lib/python2.7/site-packages/django/template/base.py", line 134, in _render<br>[Thu Aug 21 22:04:39 2014] [error] [client 77.67.85.53]     return self.nodelist.render(context)<br>[Thu Aug 21 22:04:39 2014] [error] [client 77.67.85.53]   File "/usr/lib/apx-hcc/.venv/lib/python2.7/site-packages/django/template/base.py", line 830, in render<br>[Thu Aug 21 22:04:39 2014] [error] [client 77.67.85.53]     bit = self.render_node(node, context)<br>[Thu Aug 21 22:04:39 2014] [error] [client 77.67.85.53]   File "/usr/lib/apx-hcc/.venv/lib/python2.7/site-packages/django/template/base.py", line 844, in render_node<br>[Thu Aug 21 22:04:39 2014] [error] [client 77.67.85.53]     return node.render(context)<br>[Thu Aug 21 22:04:39 2014] [error] [client 77.67.85.53]   File "/usr/lib/apx-hcc/.venv/lib/python2.7/site-packages/django/template/defaulttags.py", line 284, in render<br>[Thu Aug 21 22:04:39 2014] [error] [client 77.67.85.53]     return nodelist.render(context)<br>[Thu Aug 21 22:04:39 2014] [error] [client 77.67.85.53]   File "/usr/lib/apx-hcc/.venv/lib/python2.7/site-packages/django/template/base.py", line 830, in render<br>[Thu Aug 21 22:04:39 2014] [error] [client 77.67.85.53]     bit = self.render_node(node, context)<br>[Thu Aug 21 22:04:39 2014] [error] [client 77.67.85.53]   File "/usr/lib/apx-hcc/.venv/lib/python2.7/site-packages/django/template/base.py", line 844, in render_node<br>[Thu Aug 21 22:04:39 2014] [error] [client 77.67.85.53]     return node.render(context)<br>[Thu Aug 21 22:04:39 2014] [error] [client 77.67.85.53]   File "/usr/lib/apx-hcc/.venv/lib/python2.7/site-packages/django/template/base.py", line 881, in render<br>[Thu Aug 21 22:04:39 2014] [error] [client 77.67.85.53]     output = self.filter_expression.resolve(context)<br>[Thu Aug 21 22:04:39 2014] [error] [client 77.67.85.53]   File "/usr/lib/apx-hcc/.venv/lib/python2.7/site-packages/django/template/base.py", line 578, in resolve<br>[Thu Aug 21 22:04:39 2014] [error] [client 77.67.85.53]     obj = self.var.resolve(context)<br>[Thu Aug 21 22:04:39 2014] [error] [client 77.67.85.53]   File "/usr/lib/apx-hcc/.venv/lib/python2.7/site-packages/django/template/base.py", line 728, in resolve<br>[Thu Aug 21 22:04:39 2014] [error] [client 77.67.85.53]     value = self._resolve_lookup(context)<br>[Thu Aug 21 22:04:39 2014] [error] [client 77.67.85.53]   File "/usr/lib/apx-hcc/.venv/lib/python2.7/site-packages/django/template/base.py", line 779, in _resolve_lookup<br>[Thu Aug 21 22:04:39 2014] [error] [client 77.67.85.53]     current = current()<br>[Thu Aug 21 22:04:39 2014] [error] [client 77.67.85.53]   File "/usr/lib/apx-hcc/.venv/lib/python2.7/site-packages/django/http/request.py", line 112, in build_absolute_uri<br>[Thu Aug 21 22:04:39 2014] [error] [client 77.67.85.53]     self.get_host(), self.path)<br>[Thu Aug 21 22:04:39 2014] [error] [client 77.67.85.53]   File "/usr/lib/apx-hcc/.venv/lib/python2.7/site-packages/django/http/request.py", line 72, in get_host<br>[Thu Aug 21 22:04:39 2014] [error] [client 77.67.85.53]     "Invalid HTTP_HOST header (you may need to set ALLOWED_HOSTS): %s" % host)<br>[Thu Aug 21 22:04:39 2014] [error] [client 77.67.85.53] SuspiciousOperation: Invalid HTTP_HOST header (you may need to set ALLOWED_HOSTS): all-s3-us-ic2.digitalhub.com.akadns.net<br>[Thu Aug 21 22:04:49 2014] [error] ('production.hcc', 1408683889, {'sys_module': 'base', 'source': 'django.request', 'host': '72.46.140.186', 'session': None, 'user': u'', 'time': '1408709089814', 'datestamp': '2014-08-22T05:04:49.814069', 'level': 'ERROR', 'sys_host': 'ip-10-172-93-72', 'msecs': 813.4539127349854})<br>[Thu Aug 21 22:04:49 2014] [error] [client 204.2.160.183] mod_wsgi (pid=1758): Exception occurred processing WSGI script '/usr/lib/apx-hcc/hcc_project/hcc_project/wsgi.py'.<br>[Thu Aug 21 22:04:49 2014] [error] [client 204.2.160.183] Traceback (most recent call last):<br>[Thu Aug 21 22:04:49 2014] [error] [client 204.2.160.183]   File "/usr/lib/apx-hcc/.venv/lib/python2.7/site-packages/django/core/handlers/wsgi.py", line 255, in __call__<br>[Thu Aug 21 22:04:49 2014] [error] [client 204.2.160.183]     response = self.get_response(request)<br>[Thu Aug 21 22:04:49 2014] [error] [client 204.2.160.183]   File "/usr/lib/apx-hcc/.venv/lib/python2.7/site-packages/django/core/handlers/base.py", line 178, in get_response<br>[Thu Aug 21 22:04:49 2014] [error] [client 204.2.160.183]     response = self.handle_uncaught_exception(request, resolver, sys.exc_info())<br>[Thu Aug 21 22:04:49 2014] [error] [client 204.2.160.183]   File "/usr/lib/apx-hcc/.venv/lib/python2.7/site-packages/django/core/handlers/base.py", line 212, in handle_uncaught_exception<br>[Thu Aug 21 22:04:49 2014] [error] [client 204.2.160.183]     'request': request<br>[Thu Aug 21 22:04:49 2014] [error] [client 204.2.160.183]   File "/usr/lib64/python2.7/logging/__init__.py", line 1166, in error<br>[Thu Aug 21 22:04:49 2014] [error] [client 204.2.160.183]     self._log(ERROR, msg, args, **kwargs)<br>[Thu Aug 21 22:04:49 2014] [error] [client 204.2.160.183]   File "/usr/lib64/python2.7/logging/__init__.py", line 1258, in _log<br>[Thu Aug 21 22:04:49 2014] [error] [client 204.2.160.183]     self.handle(record)<br>[Thu Aug 21 22:04:49 2014] [error] [client 204.2.160.183]   File "/usr/lib64/python2.7/logging/__init__.py", line 1268, in handle<br>[Thu Aug 21 22:04:49 2014] [error] [client 204.2.160.183]     self.callHandlers(record)<br>[Thu Aug 21 22:04:49 2014] [error] [client 204.2.160.183]   File "/usr/lib64/python2.7/logging/__init__.py", line 1308, in callHandlers<br>[Thu Aug 21 22:04:49 2014] [error] [client 204.2.160.183]     hdlr.handle(record)<br>[Thu Aug 21 22:04:49 2014] [error] [client 204.2.160.183]   File "/usr/lib64/python2.7/logging/__init__.py", line 748, in handle<br>[Thu Aug 21 22:04:49 2014] [error] [client 204.2.160.183]     self.emit(record)<br>[Thu Aug 21 22:04:49 2014] [error] [client 204.2.160.183]   File "/usr/lib/apx-hcc/.venv/lib/python2.7/site-packages/django/utils/log.py", line 112, in emit<br>[Thu Aug 21 22:04:49 2014] [error] [client 204.2.160.183]     html_message = self.include_html and reporter.get_traceback_html() or None<br>[Thu Aug 21 22:04:49 2014] [error] [client 204.2.160.183]   File "/usr/lib/apx-hcc/.venv/lib/python2.7/site-packages/django/views/debug.py", line 298, in get_traceback_html<br>[Thu Aug 21 22:04:49 2014] [error] [client 204.2.160.183]     return t.render(c)<br>[Thu Aug 21 22:04:49 2014] [error] [client 204.2.160.183]   File "/usr/lib/apx-hcc/.venv/lib/python2.7/site-packages/django/template/base.py", line 140, in render<br>[Thu Aug 21 22:04:49 2014] [error] [client 204.2.160.183]     return self._render(context)<br>[Thu Aug 21 22:04:49 2014] [error] [client 204.2.160.183]   File "/usr/lib/apx-hcc/.venv/lib/python2.7/site-packages/django/template/base.py", line 134, in _render<br>[Thu Aug 21 22:04:49 2014] [error] [client 204.2.160.183]     return self.nodelist.render(context)<br>[Thu Aug 21 22:04:49 2014] [error] [client 204.2.160.183]   File "/usr/lib/apx-hcc/.venv/lib/python2.7/site-packages/django/template/base.py", line 830, in render<br>[Thu Aug 21 22:04:49 2014] [error] [client 204.2.160.183]     bit = self.render_node(node, context)<br>[Thu Aug 21 22:04:49 2014] [error] [client 204.2.160.183]   File "/usr/lib/apx-hcc/.venv/lib/python2.7/site-packages/django/template/base.py", line 844, in render_node<br>[Thu Aug 21 22:04:49 2014] [error] [client 204.2.160.183]     return node.render(context)<br>[Thu Aug 21 22:04:49 2014] [error] [client 204.2.160.183]   File "/usr/lib/apx-hcc/.venv/lib/python2.7/site-packages/django/template/defaulttags.py", line 284, in render<br>[Thu Aug 21 22:04:49 2014] [error] [client 204.2.160.183]     return nodelist.render(context)<br>[Thu Aug 21 22:04:49 2014] [error] [client 204.2.160.183]   File "/usr/lib/apx-hcc/.venv/lib/python2.7/site-packages/django/template/base.py", line 830, in render<br>[Thu Aug 21 22:04:49 2014] [error] [client 204.2.160.183]     bit = self.render_node(node, context)<br>[Thu Aug 21 22:04:49 2014] [error] [client 204.2.160.183]   File "/usr/lib/apx-hcc/.venv/lib/python2.7/site-packages/django/template/base.py", line 844, in render_node<br>[Thu Aug 21 22:04:49 2014] [error] [client 204.2.160.183]     return node.render(context)<br>[Thu Aug 21 22:04:49 2014] [error] [client 204.2.160.183]   File "/usr/lib/apx-hcc/.venv/lib/python2.7/site-packages/django/template/base.py", line 881, in render<br>[Thu Aug 21 22:04:49 2014] [error] [client 204.2.160.183]     output = self.filter_expression.resolve(context)<br>[Thu Aug 21 22:04:49 2014] [error] [client 204.2.160.183]   File "/usr/lib/apx-hcc/.venv/lib/python2.7/site-packages/django/template/base.py", line 578, in resolve<br>[Thu Aug 21 22:04:49 2014] [error] [client 204.2.160.183]     obj = self.var.resolve(context)<br>[Thu Aug 21 22:04:49 2014] [error] [client 204.2.160.183]   File "/usr/lib/apx-hcc/.venv/lib/python2.7/site-packages/django/template/base.py", line 728, in resolve<br>[Thu Aug 21 22:04:49 2014] [error] [client 204.2.160.183]     value = self._resolve_lookup(context)<br>[Thu Aug 21 22:04:49 2014] [error] [client 204.2.160.183]   File "/usr/lib/apx-hcc/.venv/lib/python2.7/site-packages/django/template/base.py", line 779, in _resolve_lookup<br>[Thu Aug 21 22:04:49 2014] [error] [client 204.2.160.183]     current = current()<br>[Thu Aug 21 22:04:49 2014] [error] [client 204.2.160.183]   File "/usr/lib/apx-hcc/.venv/lib/python2.7/site-packages/django/http/request.py", line 112, in build_absolute_uri<br>[Thu Aug 21 22:04:49 2014] [error] [client 204.2.160.183]     self.get_host(), self.path)<br>[Thu Aug 21 22:04:49 2014] [error] [client 204.2.160.183]   File "/usr/lib/apx-hcc/.venv/lib/python2.7/site-packages/django/http/request.py", line 72, in get_host<br>[Thu Aug 21 22:04:49 2014] [error] [client 204.2.160.183]     "Invalid HTTP_HOST header (you may need to set ALLOWED_HOSTS): %s" % host)<br>[Thu Aug 21 22:04:49 2014] [error] [client 204.2.160.183] SuspiciousOperation: Invalid HTTP_HOST header (you may need to set ALLOWED_HOSTS): all-s3-us-ic2.digitalhub.com.akadns.net<br>[Thu Aug 21 22:04:55 2014] [error] ('production.hcc', 1408683895, {'sys_module': 'base', 'source': 'django.request', 'host': '64.120.6.122', 'session': None, 'user': u'', 'time': '1408709095525', 'datestamp': '2014-08-22T05:04:55.525423', 'level': 'ERROR', 'sys_host': 'ip-10-172-93-72', 'msecs': 524.7819423675537})<br>[Thu Aug 21 22:04:55 2014] [error] [client 198.63.231.28] mod_wsgi (pid=1758): Exception occurred processing WSGI script '/usr/lib/apx-hcc/hcc_project/hcc_project/wsgi.py'.<br>[Thu Aug 21 22:04:55 2014] [error] [client 198.63.231.28] Traceback (most recent call last):<br>[Thu Aug 21 22:04:55 2014] [error] [client 198.63.231.28]   File "/usr/lib/apx-hcc/.venv/lib/python2.7/site-packages/django/core/handlers/wsgi.py", line 255, in __call__<br>[Thu Aug 21 22:04:55 2014] [error] [client 198.63.231.28]     response = self.get_response(request)<br>[Thu Aug 21 22:04:55 2014] [error] [client 198.63.231.28]   File "/usr/lib/apx-hcc/.venv/lib/python2.7/site-packages/django/core/handlers/base.py", line 178, in get_response<br>[Thu Aug 21 22:04:55 2014] [error] [client 198.63.231.28]     response = self.handle_uncaught_exception(request, resolver, sys.exc_info())<br>[Thu Aug 21 22:04:55 2014] [error] [client 198.63.231.28]   File "/usr/lib/apx-hcc/.venv/lib/python2.7/site-packages/django/core/handlers/base.py", line 212, in handle_uncaught_exception<br>[Thu Aug 21 22:04:55 2014] [error] [client 198.63.231.28]     'request': request<br>[Thu Aug 21 22:04:55 2014] [error] [client 198.63.231.28]   File "/usr/lib64/python2.7/logging/__init__.py", line 1166, in error<br>[Thu Aug 21 22:04:55 2014] [error] [client 198.63.231.28]     self._log(ERROR, msg, args, **kwargs)<br>[Thu Aug 21 22:04:55 2014] [error] [client 198.63.231.28]   File "/usr/lib64/python2.7/logging/__init__.py", line 1258, in _log<br>[Thu Aug 21 22:04:55 2014] [error] [client 198.63.231.28]     self.handle(record)<br>[Thu Aug 21 22:04:55 2014] [error] [client 198.63.231.28]   File "/usr/lib64/python2.7/logging/__init__.py", line 1268, in handle<br>[Thu Aug 21 22:04:55 2014] [error] [client 198.63.231.28]     self.callHandlers(record)<br>[Thu Aug 21 22:04:55 2014] [error] [client 198.63.231.28]   File "/usr/lib64/python2.7/logging/__init__.py", line 1308, in callHandlers<br>[Thu Aug 21 22:04:55 2014] [error] [client 198.63.231.28]     hdlr.handle(record)<br>[Thu Aug 21 22:04:55 2014] [error] [client 198.63.231.28]   File "/usr/lib64/python2.7/logging/__init__.py", line 748, in handle<br>[Thu Aug 21 22:04:55 2014] [error] [client 198.63.231.28]     self.emit(record)<br>[Thu Aug 21 22:04:55 2014] [error] [client 198.63.231.28]   File "/usr/lib/apx-hcc/.venv/lib/python2.7/site-packages/django/utils/log.py", line 112, in emit<br>[Thu Aug 21 22:04:55 2014] [error] [client 198.63.231.28]     html_message = self.include_html and reporter.get_traceback_html() or None<br>[Thu Aug 21 22:04:55 2014] [error] [client 198.63.231.28]   File "/usr/lib/apx-hcc/.venv/lib/python2.7/site-packages/django/views/debug.py", line 298, in get_traceback_html<br>[Thu Aug 21 22:04:55 2014] [error] [client 198.63.231.28]     return t.render(c)<br>[Thu Aug 21 22:04:55 2014] [error] [client 198.63.231.28]   File "/usr/lib/apx-hcc/.venv/lib/python2.7/site-packages/django/template/base.py", line 140, in render<br>[Thu Aug 21 22:04:55 2014] [error] [client 198.63.231.28]     return self._render(context)<br>[Thu Aug 21 22:04:55 2014] [error] [client 198.63.231.28]   File "/usr/lib/apx-hcc/.venv/lib/python2.7/site-packages/django/template/base.py", line 134, in _render<br>[Thu Aug 21 22:04:55 2014] [error] [client 198.63.231.28]     return self.nodelist.render(context)<br>[Thu Aug 21 22:04:55 2014] [error] [client 198.63.231.28]   File "/usr/lib/apx-hcc/.venv/lib/python2.7/site-packages/django/template/base.py", line 830, in render<br>[Thu Aug 21 22:04:55 2014] [error] [client 198.63.231.28]     bit = self.render_node(node, context)<br>[Thu Aug 21 22:04:55 2014] [error] [client 198.63.231.28]   File "/usr/lib/apx-hcc/.venv/lib/python2.7/site-packages/django/template/base.py", line 844, in render_node<br>[Thu Aug 21 22:04:55 2014] [error] [client 198.63.231.28]     return node.render(context)<br>[Thu Aug 21 22:04:55 2014] [error] [client 198.63.231.28]   File "/usr/lib/apx-hcc/.venv/lib/python2.7/site-packages/django/template/defaulttags.py", line 284, in render<br>[Thu Aug 21 22:04:55 2014] [error] [client 198.63.231.28]     return nodelist.render(context)<br>[Thu Aug 21 22:04:55 2014] [error] [client 198.63.231.28]   File "/usr/lib/apx-hcc/.venv/lib/python2.7/site-packages/django/template/base.py", line 830, in render<br>[Thu Aug 21 22:04:55 2014] [error] [client 198.63.231.28]     bit = self.render_node(node, context)<br>[Thu Aug 21 22:04:55 2014] [error] [client 198.63.231.28]   File "/usr/lib/apx-hcc/.venv/lib/python2.7/site-packages/django/template/base.py", line 844, in render_node<br>[Thu Aug 21 22:04:55 2014] [error] [client 198.63.231.28]     return node.render(context)<br>[Thu Aug 21 22:04:55 2014] [error] [client 198.63.231.28]   File "/usr/lib/apx-hcc/.venv/lib/python2.7/site-packages/django/template/base.py", line 881, in render<br>[Thu Aug 21 22:04:55 2014] [error] [client 198.63.231.28]     output = self.filter_expression.resolve(context)<br>[Thu Aug 21 22:04:55 2014] [error] [client 198.63.231.28]   File "/usr/lib/apx-hcc/.venv/lib/python2.7/site-packages/django/template/base.py", line 578, in resolve<br>[Thu Aug 21 22:04:55 2014] [error] [client 198.63.231.28]     obj = self.var.resolve(context)<br>[Thu Aug 21 22:04:55 2014] [error] [client 198.63.231.28]   File "/usr/lib/apx-hcc/.venv/lib/python2.7/site-packages/django/template/base.py", line 728, in resolve<br>[Thu Aug 21 22:04:55 2014] [error] [client 198.63.231.28]     value = self._resolve_lookup(context)<br>[Thu Aug 21 22:04:55 2014] [error] [client 198.63.231.28]   File "/usr/lib/apx-hcc/.venv/lib/python2.7/site-packages/django/template/base.py", line 779, in _resolve_lookup<br>[Thu Aug 21 22:04:55 2014] [error] [client 198.63.231.28]     current = current()<br>[Thu Aug 21 22:04:55 2014] [error] [client 198.63.231.28]   File "/usr/lib/apx-hcc/.venv/lib/python2.7/site-packages/django/http/request.py", line 112, in build_absolute_uri<br>[Thu Aug 21 22:04:55 2014] [error] [client 198.63.231.28]     self.get_host(), self.path)<br>[Thu Aug 21 22:04:55 2014] [error] [client 198.63.231.28]   File "/usr/lib/apx-hcc/.venv/lib/python2.7/site-packages/django/http/request.py", line 72, in get_host<br>[Thu Aug 21 22:04:55 2014] [error] [client 198.63.231.28]     "Invalid HTTP_HOST header (you may need to set ALLOWED_HOSTS): %s" % host)<br>[Thu Aug 21 22:04:55 2014] [error] [client 198.63.231.28] SuspiciousOperation: Invalid HTTP_HOST header (you may need to set ALLOWED_HOSTS): all-s3-us-ic2.digitalhub.com.akadns.net<br>[Thu Aug 21 22:05:05 2014] [error] ('production.hcc', 1408683905, {'sys_module': 'base', 'source': 'django.request', 'host': '72.46.140.186', 'session': None, 'user': u'', 'time': '1408709105784', 'datestamp': '2014-08-22T05:05:05.784344', 'level': 'ERROR', 'sys_host': 'ip-10-172-93-72', 'msecs': 783.7190628051758})<br>[Thu Aug 21 22:05:05 2014] [error] [client 72.247.120.220] mod_wsgi (pid=1758): Exception occurred processing WSGI script '/usr/lib/apx-hcc/hcc_project/hcc_project/wsgi.py'.<br>[Thu Aug 21 22:05:05 2014] [error] [client 72.247.120.220] Traceback (most recent call last):<br>[Thu Aug 21 22:05:05 2014] [error] [client 72.247.120.220]   File "/usr/lib/apx-hcc/.venv/lib/python2.7/site-packages/django/core/handlers/wsgi.py", line 255, in __call__<br>[Thu Aug 21 22:05:05 2014] [error] [client 72.247.120.220]     response = self.get_response(request)<br>[Thu Aug 21 22:05:05 2014] [error] [client 72.247.120.220]   File "/usr/lib/apx-hcc/.venv/lib/python2.7/site-packages/django/core/handlers/base.py", line 178, in get_response<br>[Thu Aug 21 22:05:05 2014] [error] [client 72.247.120.220]     response = self.handle_uncaught_exception(request, resolver, sys.exc_info())<br>[Thu Aug 21 22:05:05 2014] [error] [client 72.247.120.220]   File "/usr/lib/apx-hcc/.venv/lib/python2.7/site-packages/django/core/handlers/base.py", line 212, in handle_uncaught_exception<br>[Thu Aug 21 22:05:05 2014] [error] [client 72.247.120.220]     'request': request<br>[Thu Aug 21 22:05:05 2014] [error] [client 72.247.120.220]   File "/usr/lib64/python2.7/logging/__init__.py", line 1166, in error<br>[Thu Aug 21 22:05:05 2014] [error] [client 72.247.120.220]     self._log(ERROR, msg, args, **kwargs)<br>[Thu Aug 21 22:05:05 2014] [error] [client 72.247.120.220]   File "/usr/lib64/python2.7/logging/__init__.py", line 1258, in _log<br>[Thu Aug 21 22:05:05 2014] [error] [client 72.247.120.220]     self.handle(record)<br>[Thu Aug 21 22:05:05 2014] [error] [client 72.247.120.220]   File "/usr/lib64/python2.7/logging/__init__.py", line 1268, in handle<br>[Thu Aug 21 22:05:05 2014] [error] [client 72.247.120.220]     self.callHandlers(record)<br>[Thu Aug 21 22:05:05 2014] [error] [client 72.247.120.220]   File "/usr/lib64/python2.7/logging/__init__.py", line 1308, in callHandlers<br>[Thu Aug 21 22:05:05 2014] [error] [client 72.247.120.220]     hdlr.handle(record)<br>[Thu Aug 21 22:05:05 2014] [error] [client 72.247.120.220]   File "/usr/lib64/python2.7/logging/__init__.py", line 748, in handle<br>[Thu Aug 21 22:05:05 2014] [error] [client 72.247.120.220]     self.emit(record)<br>[Thu Aug 21 22:05:05 2014] [error] [client 72.247.120.220]   File "/usr/lib/apx-hcc/.venv/lib/python2.7/site-packages/django/utils/log.py", line 112, in emit<br>[Thu Aug 21 22:05:05 2014] [error] [client 72.247.120.220]     html_message = self.include_html and reporter.get_traceback_html() or None<br>[Thu Aug 21 22:05:05 2014] [error] [client 72.247.120.220]   File "/usr/lib/apx-hcc/.venv/lib/python2.7/site-packages/django/views/debug.py", line 298, in get_traceback_html<br>[Thu Aug 21 22:05:05 2014] [error] [client 72.247.120.220]     return t.render(c)<br>[Thu Aug 21 22:05:05 2014] [error] [client 72.247.120.220]   File "/usr/lib/apx-hcc/.venv/lib/python2.7/site-packages/django/template/base.py", line 140, in render<br>[Thu Aug 21 22:05:05 2014] [error] [client 72.247.120.220]     return self._render(context)<br>[Thu Aug 21 22:05:05 2014] [error] [client 72.247.120.220]   File "/usr/lib/apx-hcc/.venv/lib/python2.7/site-packages/django/template/base.py", line 134, in _render<br>[Thu Aug 21 22:05:05 2014] [error] [client 72.247.120.220]     return self.nodelist.render(context)<br>[Thu Aug 21 22:05:05 2014] [error] [client 72.247.120.220]   File "/usr/lib/apx-hcc/.venv/lib/python2.7/site-packages/django/template/base.py", line 830, in render<br>[Thu Aug 21 22:05:05 2014] [error] [client 72.247.120.220]     bit = self.render_node(node, context)<br>[Thu Aug 21 22:05:05 2014] [error] [client 72.247.120.220]   File "/usr/lib/apx-hcc/.venv/lib/python2.7/site-packages/django/template/base.py", line 844, in render_node<br>[Thu Aug 21 22:05:05 2014] [error] [client 72.247.120.220]     return node.render(context)<br>[Thu Aug 21 22:05:05 2014] [error] [client 72.247.120.220]   File "/usr/lib/apx-hcc/.venv/lib/python2.7/site-packages/django/template/defaulttags.py", line 284, in render<br>[Thu Aug 21 22:05:05 2014] [error] [client 72.247.120.220]     return nodelist.render(context)<br>[Thu Aug 21 22:05:05 2014] [error] [client 72.247.120.220]   File "/usr/lib/apx-hcc/.venv/lib/python2.7/site-packages/django/template/base.py", line 830, in render<br>[Thu Aug 21 22:05:05 2014] [error] [client 72.247.120.220]     bit = self.render_node(node, context)<br>[Thu Aug 21 22:05:05 2014] [error] [client 72.247.120.220]   File "/usr/lib/apx-hcc/.venv/lib/python2.7/site-packages/django/template/base.py", line 844, in render_node<br>[Thu Aug 21 22:05:05 2014] [error] [client 72.247.120.220]     return node.render(context)<br>[Thu Aug 21 22:05:05 2014] [error] [client 72.247.120.220]   File "/usr/lib/apx-hcc/.venv/lib/python2.7/site-packages/django/template/base.py", line 881, in render<br>[Thu Aug 21 22:05:05 2014] [error] [client 72.247.120.220]     output = self.filter_expression.resolve(context)<br>[Thu Aug 21 22:05:05 2014] [error] [client 72.247.120.220]   File "/usr/lib/apx-hcc/.venv/lib/python2.7/site-packages/django/template/base.py", line 578, in resolve<br>[Thu Aug 21 22:05:05 2014] [error] [client 72.247.120.220]     obj = self.var.resolve(context)<br>[Thu Aug 21 22:05:05 2014] [error] [client 72.247.120.220]   File "/usr/lib/apx-hcc/.venv/lib/python2.7/site-packages/django/template/base.py", line 728, in resolve<br>[Thu Aug 21 22:05:05 2014] [error] [client 72.247.120.220]     value = self._resolve_lookup(context)<br>[Thu Aug 21 22:05:05 2014] [error] [client 72.247.120.220]   File "/usr/lib/apx-hcc/.venv/lib/python2.7/site-packages/django/template/base.py", line 779, in _resolve_lookup<br>[Thu Aug 21 22:05:05 2014] [error] [client 72.247.120.220]     current = current()<br>[Thu Aug 21 22:05:05 2014] [error] [client 72.247.120.220]   File "/usr/lib/apx-hcc/.venv/lib/python2.7/site-packages/django/http/request.py", line 112, in build_absolute_uri<br>[Thu Aug 21 22:05:05 2014] [error] [client 72.247.120.220]     self.get_host(), self.path)<br>[Thu Aug 21 22:05:05 2014] [error] [client 72.247.120.220]   File "/usr/lib/apx-hcc/.venv/lib/python2.7/site-packages/django/http/request.py", line 72, in get_host<br>[Thu Aug 21 22:05:05 2014] [error] [client 72.247.120.220]     "Invalid HTTP_HOST header (you may need to set ALLOWED_HOSTS): %s" % host)<br>[Thu Aug 21 22:05:05 2014] [error] [client 72.247.120.220] SuspiciousOperation: Invalid HTTP_HOST header (you may need to set ALLOWED_HOSTS): all-s3-us-ic2.digitalhub.com.akadns.net<br>[Thu Aug 21 22:05:36 2014] [error] ('production.hcc', 1408683936, {'sys_module': 'base', 'source': 'django.request', 'host': '64.120.6.122', 'session': None, 'user': u'', 'time': '1408709136162', 'datestamp': '2014-08-22T05:05:36.162718', 'level': 'ERROR', 'sys_host': 'ip-10-172-93-72', 'msecs': 162.1260643005371})<br>[Thu Aug 21 22:05:36 2014] [error] [client 72.247.120.220] mod_wsgi (pid=1758): Exception occurred processing WSGI script '/usr/lib/apx-hcc/hcc_project/hcc_project/wsgi.py'.<br>[Thu Aug 21 22:05:36 2014] [error] [client 72.247.120.220] Traceback (most recent call last):<br>[Thu Aug 21 22:05:36 2014] [error] [client 72.247.120.220]   File "/usr/lib/apx-hcc/.venv/lib/python2.7/site-packages/django/core/handlers/wsgi.py", line 255, in __call__<br>[Thu Aug 21 22:05:36 2014] [error] [client 72.247.120.220]     response = self.get_response(request)<br>[Thu Aug 21 22:05:36 2014] [error] [client 72.247.120.220]   File "/usr/lib/apx-hcc/.venv/lib/python2.7/site-packages/django/core/handlers/base.py", line 178, in get_response<br>[Thu Aug 21 22:05:36 2014] [error] [client 72.247.120.220]     response = self.handle_uncaught_exception(request, resolver, sys.exc_info())<br>[Thu Aug 21 22:05:36 2014] [error] [client 72.247.120.220]   File "/usr/lib/apx-hcc/.venv/lib/python2.7/site-packages/django/core/handlers/base.py", line 212, in handle_uncaught_exception<br>[Thu Aug 21 22:05:36 2014] [error] [client 72.247.120.220]     'request': request<br>[Thu Aug 21 22:05:36 2014] [error] [client 72.247.120.220]   File "/usr/lib64/python2.7/logging/__init__.py", line 1166, in error<br>[Thu Aug 21 22:05:36 2014] [error] [client 72.247.120.220]     self._log(ERROR, msg, args, **kwargs)<br>[Thu Aug 21 22:05:36 2014] [error] [client 72.247.120.220]   File "/usr/lib64/python2.7/logging/__init__.py", line 1258, in _log<br>[Thu Aug 21 22:05:36 2014] [error] [client 72.247.120.220]     self.handle(record)<br>[Thu Aug 21 22:05:36 2014] [error] [client 72.247.120.220]   File "/usr/lib64/python2.7/logging/__init__.py", line 1268, in handle<br>[Thu Aug 21 22:05:36 2014] [error] [client 72.247.120.220]     self.callHandlers(record)<br>[Thu Aug 21 22:05:36 2014] [error] [client 72.247.120.220]   File "/usr/lib64/python2.7/logging/__init__.py", line 1308, in callHandlers<br>[Thu Aug 21 22:05:36 2014] [error] [client 72.247.120.220]     hdlr.handle(record)<br>[Thu Aug 21 22:05:36 2014] [error] [client 72.247.120.220]   File "/usr/lib64/python2.7/logging/__init__.py", line 748, in handle<br>[Thu Aug 21 22:05:36 2014] [error] [client 72.247.120.220]     self.emit(record)<br>[Thu Aug 21 22:05:36 2014] [error] [client 72.247.120.220]   File "/usr/lib/apx-hcc/.venv/lib/python2.7/site-packages/django/utils/log.py", line 112, in emit<br>[Thu Aug 21 22:05:36 2014] [error] [client 72.247.120.220]     html_message = self.include_html and reporter.get_traceback_html() or None<br>[Thu Aug 21 22:05:36 2014] [error] [client 72.247.120.220]   File "/usr/lib/apx-hcc/.venv/lib/python2.7/site-packages/django/views/debug.py", line 298, in get_traceback_html<br>[Thu Aug 21 22:05:36 2014] [error] [client 72.247.120.220]     return t.render(c)<br>[Thu Aug 21 22:05:36 2014] [error] [client 72.247.120.220]   File "/usr/lib/apx-hcc/.venv/lib/python2.7/site-packages/django/template/base.py", line 140, in render<br>[Thu Aug 21 22:05:36 2014] [error] [client 72.247.120.220]     return self._render(context)<br>[Thu Aug 21 22:05:36 2014] [error] [client 72.247.120.220]   File "/usr/lib/apx-hcc/.venv/lib/python2.7/site-packages/django/template/base.py", line 134, in _render<br>[Thu Aug 21 22:05:36 2014] [error] [client 72.247.120.220]     return self.nodelist.render(context)<br>[Thu Aug 21 22:05:36 2014] [error] [client 72.247.120.220]   File "/usr/lib/apx-hcc/.venv/lib/python2.7/site-packages/django/template/base.py", line 830, in render<br>[Thu Aug 21 22:05:36 2014] [error] [client 72.247.120.220]     bit = self.render_node(node, context)<br>[Thu Aug 21 22:05:36 2014] [error] [client 72.247.120.220]   File "/usr/lib/apx-hcc/.venv/lib/python2.7/site-packages/django/template/base.py", line 844, in render_node<br>[Thu Aug 21 22:05:36 2014] [error] [client 72.247.120.220]     return node.render(context)<br>[Thu Aug 21 22:05:36 2014] [error] [client 72.247.120.220]   File "/usr/lib/apx-hcc/.venv/lib/python2.7/site-packages/django/template/defaulttags.py", line 284, in render<br>[Thu Aug 21 22:05:36 2014] [error] [client 72.247.120.220]     return nodelist.render(context)<br>[Thu Aug 21 22:05:36 2014] [error] [client 72.247.120.220]   File "/usr/lib/apx-hcc/.venv/lib/python2.7/site-packages/django/template/base.py", line 830, in render<br>[Thu Aug 21 22:05:36 2014] [error] [client 72.247.120.220]     bit = self.render_node(node, context)<br>[Thu Aug 21 22:05:36 2014] [error] [client 72.247.120.220]   File "/usr/lib/apx-hcc/.venv/lib/python2.7/site-packages/django/template/base.py", line 844, in render_node<br>[Thu Aug 21 22:05:36 2014] [error] [client 72.247.120.220]     return node.render(context)<br>[Thu Aug 21 22:05:36 2014] [error] [client 72.247.120.220]   File "/usr/lib/apx-hcc/.venv/lib/python2.7/site-packages/django/template/base.py", line 881, in render<br>[Thu Aug 21 22:05:36 2014] [error] [client 72.247.120.220]     output = self.filter_expression.resolve(context)<br>[Thu Aug 21 22:05:36 2014] [error] [client 72.247.120.220]   File "/usr/lib/apx-hcc/.venv/lib/python2.7/site-packages/django/template/base.py", line 578, in resolve<br>[Thu Aug 21 22:05:36 2014] [error] [client 72.247.120.220]     obj = self.var.resolve(context)<br>[Thu Aug 21 22:05:36 2014] [error] [client 72.247.120.220]   File "/usr/lib/apx-hcc/.venv/lib/python2.7/site-packages/django/template/base.py", line 728, in resolve<br>[Thu Aug 21 22:05:36 2014] [error] [client 72.247.120.220]     value = self._resolve_lookup(context)<br>[Thu Aug 21 22:05:36 2014] [error] [client 72.247.120.220]   File "/usr/lib/apx-hcc/.venv/lib/python2.7/site-packages/django/template/base.py", line 779, in _resolve_lookup<br>[Thu Aug 21 22:05:36 2014] [error] [client 72.247.120.220]     current = current()<br>[Thu Aug 21 22:05:36 2014] [error] [client 72.247.120.220]   File "/usr/lib/apx-hcc/.venv/lib/python2.7/site-packages/django/http/request.py", line 112, in build_absolute_uri<br>[Thu Aug 21 22:05:36 2014] [error] [client 72.247.120.220]     self.get_host(), self.path)<br>[Thu Aug 21 22:05:36 2014] [error] [client 72.247.120.220]   File "/usr/lib/apx-hcc/.venv/lib/python2.7/site-packages/django/http/request.py", line 72, in get_host<br>[Thu Aug 21 22:05:36 2014] [error] [client 72.247.120.220]     "Invalid HTTP_HOST header (you may need to set ALLOWED_HOSTS): %s" % host)<br>[Thu Aug 21 22:05:36 2014] [error] [client 72.247.120.220] SuspiciousOperation: Invalid HTTP_HOST header (you may need to set ALLOWED_HOSTS): all-s3-us-ic2.digitalhub.com.akadns.net<br>[Thu Aug 21 22:05:39 2014] [error] ('production.hcc', 1408683939, {'sys_module': 'base', 'source': 'django.request', 'host': '72.46.140.186', 'session': None, 'user': u'', 'time': '1408709139092', 'datestamp': '2014-08-22T05:05:39.092913', 'level': 'ERROR', 'sys_host': 'ip-10-172-93-72', 'msecs': 92.28801727294922})<br>[Thu Aug 21 22:05:39 2014] [error] [client 205.185.205.132] mod_wsgi (pid=1758): Exception occurred processing WSGI script '/usr/lib/apx-hcc/hcc_project/hcc_project/wsgi.py'.<br>[Thu Aug 21 22:05:39 2014] [error] [client 205.185.205.132] Traceback (most recent call last):<br>[Thu Aug 21 22:05:39 2014] [error] [client 205.185.205.132]   File "/usr/lib/apx-hcc/.venv/lib/python2.7/site-packages/django/core/handlers/wsgi.py", line 255, in __call__<br>[Thu Aug 21 22:05:39 2014] [error] [client 205.185.205.132]     response = self.get_response(request)<br>[Thu Aug 21 22:05:39 2014] [error] [client 205.185.205.132]   File "/usr/lib/apx-hcc/.venv/lib/python2.7/site-packages/django/core/handlers/base.py", line 178, in get_response<br>[Thu Aug 21 22:05:39 2014] [error] [client 205.185.205.132]     response = self.handle_uncaught_exception(request, resolver, sys.exc_info())<br>[Thu Aug 21 22:05:39 2014] [error] [client 205.185.205.132]   File "/usr/lib/apx-hcc/.venv/lib/python2.7/site-packages/django/core/handlers/base.py", line 212, in handle_uncaught_exception<br>[Thu Aug 21 22:05:39 2014] [error] [client 205.185.205.132]     'request': request<br>[Thu Aug 21 22:05:39 2014] [error] [client 205.185.205.132]   File "/usr/lib64/python2.7/logging/__init__.py", line 1166, in error<br>[Thu Aug 21 22:05:39 2014] [error] [client 205.185.205.132]     self._log(ERROR, msg, args, **kwargs)<br>[Thu Aug 21 22:05:39 2014] [error] [client 205.185.205.132]   File "/usr/lib64/python2.7/logging/__init__.py", line 1258, in _log<br>[Thu Aug 21 22:05:39 2014] [error] [client 205.185.205.132]     self.handle(record)<br>[Thu Aug 21 22:05:39 2014] [error] [client 205.185.205.132]   File "/usr/lib64/python2.7/logging/__init__.py", line 1268, in handle<br>[Thu Aug 21 22:05:39 2014] [error] [client 205.185.205.132]     self.callHandlers(record)<br>[Thu Aug 21 22:05:39 2014] [error] [client 205.185.205.132]   File "/usr/lib64/python2.7/logging/__init__.py", line 1308, in callHandlers<br>[Thu Aug 21 22:05:39 2014] [error] [client 205.185.205.132]     hdlr.handle(record)<br>[Thu Aug 21 22:05:39 2014] [error] [client 205.185.205.132]   File "/usr/lib64/python2.7/logging/__init__.py", line 748, in handle<br>[Thu Aug 21 22:05:39 2014] [error] [client 205.185.205.132]     self.emit(record)<br>[Thu Aug 21 22:05:39 2014] [error] [client 205.185.205.132]   File "/usr/lib/apx-hcc/.venv/lib/python2.7/site-packages/django/utils/log.py", line 112, in emit<br>[Thu Aug 21 22:05:39 2014] [error] [client 205.185.205.132]     html_message = self.include_html and reporter.get_traceback_html() or None<br>[Thu Aug 21 22:05:39 2014] [error] [client 205.185.205.132]   File "/usr/lib/apx-hcc/.venv/lib/python2.7/site-packages/django/views/debug.py", line 298, in get_traceback_html<br>[Thu Aug 21 22:05:39 2014] [error] [client 205.185.205.132]     return t.render(c)<br>[Thu Aug 21 22:05:39 2014] [error] [client 205.185.205.132]   File "/usr/lib/apx-hcc/.venv/lib/python2.7/site-packages/django/template/base.py", line 140, in render<br>[Thu Aug 21 22:05:39 2014] [error] [client 205.185.205.132]     return self._render(context)<br>[Thu Aug 21 22:05:39 2014] [error] [client 205.185.205.132]   File "/usr/lib/apx-hcc/.venv/lib/python2.7/site-packages/django/template/base.py", line 134, in _render<br>[Thu Aug 21 22:05:39 2014] [error] [client 205.185.205.132]     return self.nodelist.render(context)<br>[Thu Aug 21 22:05:39 2014] [error] [client 205.185.205.132]   File "/usr/lib/apx-hcc/.venv/lib/python2.7/site-packages/django/template/base.py", line 830, in render<br>[Thu Aug 21 22:05:39 2014] [error] [client 205.185.205.132]     bit = self.render_node(node, context)<br>[Thu Aug 21 22:05:39 2014] [error] [client 205.185.205.132]   File "/usr/lib/apx-hcc/.venv/lib/python2.7/site-packages/django/template/base.py", line 844, in render_node<br>[Thu Aug 21 22:05:39 2014] [error] [client 205.185.205.132]     return node.render(context)<br>[Thu Aug 21 22:05:39 2014] [error] [client 205.185.205.132]   File "/usr/lib/apx-hcc/.venv/lib/python2.7/site-packages/django/template/defaulttags.py", line 284, in render<br>[Thu Aug 21 22:05:39 2014] [error] [client 205.185.205.132]     return nodelist.render(context)<br>[Thu Aug 21 22:05:39 2014] [error] [client 205.185.205.132]   File "/usr/lib/apx-hcc/.venv/lib/python2.7/site-packages/django/template/base.py", line 830, in render<br>[Thu Aug 21 22:05:39 2014] [error] [client 205.185.205.132]     bit = self.render_node(node, context)<br>[Thu Aug 21 22:05:39 2014] [error] [client 205.185.205.132]   File "/usr/lib/apx-hcc/.venv/lib/python2.7/site-packages/django/template/base.py", line 844, in render_node<br>[Thu Aug 21 22:05:39 2014] [error] [client 205.185.205.132]     return node.render(context)<br>[Thu Aug 21 22:05:39 2014] [error] [client 205.185.205.132]   File "/usr/lib/apx-hcc/.venv/lib/python2.7/site-packages/django/template/base.py", line 881, in render<br>[Thu Aug 21 22:05:39 2014] [error] [client 205.185.205.132]     output = self.filter_expression.resolve(context)<br>[Thu Aug 21 22:05:39 2014] [error] [client 205.185.205.132]   File "/usr/lib/apx-hcc/.venv/lib/python2.7/site-packages/django/template/base.py", line 578, in resolve<br>[Thu Aug 21 22:05:39 2014] [error] [client 205.185.205.132]     obj = self.var.resolve(context)<br>[Thu Aug 21 22:05:39 2014] [error] [client 205.185.205.132]   File "/usr/lib/apx-hcc/.venv/lib/python2.7/site-packages/django/template/base.py", line 728, in resolve<br>[Thu Aug 21 22:05:39 2014] [error] [client 205.185.205.132]     value = self._resolve_lookup(context)<br>[Thu Aug 21 22:05:39 2014] [error] [client 205.185.205.132]   File "/usr/lib/apx-hcc/.venv/lib/python2.7/site-packages/django/template/base.py", line 779, in _resolve_lookup<br>[Thu Aug 21 22:05:39 2014] [error] [client 205.185.205.132]     current = current()<br>[Thu Aug 21 22:05:39 2014] [error] [client 205.185.205.132]   File "/usr/lib/apx-hcc/.venv/lib/python2.7/site-packages/django/http/request.py", line 112, in build_absolute_uri<br>[Thu Aug 21 22:05:39 2014] [error] [client 205.185.205.132]     self.get_host(), self.path)<br>[Thu Aug 21 22:05:39 2014] [error] [client 205.185.205.132]   File "/usr/lib/apx-hcc/.venv/lib/python2.7/site-packages/django/http/request.py", line 72, in get_host<br>[Thu Aug 21 22:05:39 2014] [error] [client 205.185.205.132]     "Invalid HTTP_HOST header (you may need to set ALLOWED_HOSTS): %s" % host)<br>[Thu Aug 21 22:05:39 2014] [error] [client 205.185.205.132] SuspiciousOperation: Invalid HTTP_HOST header (you may need to set ALLOWED_HOSTS): all-s3-us-ic2.digitalhub.com.akadns.net<br>[Thu Aug 21 22:06:06 2014] [error] ('production.hcc', 1408683966, {'sys_module': 'base', 'source': 'django.request', 'host': '64.120.6.122', 'session': None, 'user': u'', 'time': '1408709166536', 'datestamp': '2014-08-22T05:06:06.536141', 'level': 'ERROR', 'sys_host': 'ip-10-172-93-72', 'msecs': 535.5420112609863})<br>[Thu Aug 21 22:06:06 2014] [error] [client 72.247.120.220] mod_wsgi (pid=1758): Exception occurred processing WSGI script '/usr/lib/apx-hcc/hcc_project/hcc_project/wsgi.py'.<br>[Thu Aug 21 22:06:06 2014] [error] [client 72.247.120.220] Traceback (most recent call last):<br>[Thu Aug 21 22:06:06 2014] [error] [client 72.247.120.220]   File "/usr/lib/apx-hcc/.venv/lib/python2.7/site-packages/django/core/handlers/wsgi.py", line 255, in __call__<br>[Thu Aug 21 22:06:06 2014] [error] [client 72.247.120.220]     response = self.get_response(request)<br>[Thu Aug 21 22:06:06 2014] [error] [client 72.247.120.220]   File "/usr/lib/apx-hcc/.venv/lib/python2.7/site-packages/django/core/handlers/base.py", line 178, in get_response<br>[Thu Aug 21 22:06:06 2014] [error] [client 72.247.120.220]     response = self.handle_uncaught_exception(request, resolver, sys.exc_info())<br>[Thu Aug 21 22:06:06 2014] [error] [client 72.247.120.220]   File "/usr/lib/apx-hcc/.venv/lib/python2.7/site-packages/django/core/handlers/base.py", line 212, in handle_uncaught_exception<br>[Thu Aug 21 22:06:06 2014] [error] [client 72.247.120.220]     'request': request<br>[Thu Aug 21 22:06:06 2014] [error] [client 72.247.120.220]   File "/usr/lib64/python2.7/logging/__init__.py", line 1166, in error<br>[Thu Aug 21 22:06:06 2014] [error] [client 72.247.120.220]     self._log(ERROR, msg, args, **kwargs)<br>[Thu Aug 21 22:06:06 2014] [error] [client 72.247.120.220]   File "/usr/lib64/python2.7/logging/__init__.py", line 1258, in _log<br>[Thu Aug 21 22:06:06 2014] [error] [client 72.247.120.220]     self.handle(record)<br>[Thu Aug 21 22:06:06 2014] [error] [client 72.247.120.220]   File "/usr/lib64/python2.7/logging/__init__.py", line 1268, in handle<br>[Thu Aug 21 22:06:06 2014] [error] [client 72.247.120.220]     self.callHandlers(record)<br>[Thu Aug 21 22:06:06 2014] [error] [client 72.247.120.220]   File "/usr/lib64/python2.7/logging/__init__.py", line 1308, in callHandlers<br>[Thu Aug 21 22:06:06 2014] [error] [client 72.247.120.220]     hdlr.handle(record)<br>[Thu Aug 21 22:06:06 2014] [error] [client 72.247.120.220]   File "/usr/lib64/python2.7/logging/__init__.py", line 748, in handle<br>[Thu Aug 21 22:06:06 2014] [error] [client 72.247.120.220]     self.emit(record)<br>[Thu Aug 21 22:06:06 2014] [error] [client 72.247.120.220]   File "/usr/lib/apx-hcc/.venv/lib/python2.7/site-packages/django/utils/log.py", line 112, in emit<br>[Thu Aug 21 22:06:06 2014] [error] [client 72.247.120.220]     html_message = self.include_html and reporter.get_traceback_html() or None<br>[Thu Aug 21 22:06:06 2014] [error] [client 72.247.120.220]   File "/usr/lib/apx-hcc/.venv/lib/python2.7/site-packages/django/views/debug.py", line 298, in get_traceback_html<br>[Thu Aug 21 22:06:06 2014] [error] [client 72.247.120.220]     return t.render(c)<br>[Thu Aug 21 22:06:06 2014] [error] [client 72.247.120.220]   File "/usr/lib/apx-hcc/.venv/lib/python2.7/site-packages/django/template/base.py", line 140, in render<br>[Thu Aug 21 22:06:06 2014] [error] [client 72.247.120.220]     return self._render(context)<br>[Thu Aug 21 22:06:06 2014] [error] [client 72.247.120.220]   File "/usr/lib/apx-hcc/.venv/lib/python2.7/site-packages/django/template/base.py", line 134, in _render<br>[Thu Aug 21 22:06:06 2014] [error] [client 72.247.120.220]     return self.nodelist.render(context)<br>[Thu Aug 21 22:06:06 2014] [error] [client 72.247.120.220]   File "/usr/lib/apx-hcc/.venv/lib/python2.7/site-packages/django/template/base.py", line 830, in render<br>[Thu Aug 21 22:06:06 2014] [error] [client 72.247.120.220]     bit = self.render_node(node, context)<br>[Thu Aug 21 22:06:06 2014] [error] [client 72.247.120.220]   File "/usr/lib/apx-hcc/.venv/lib/python2.7/site-packages/django/template/base.py", line 844, in render_node<br>[Thu Aug 21 22:06:06 2014] [error] [client 72.247.120.220]     return node.render(context)<br>[Thu Aug 21 22:06:06 2014] [error] [client 72.247.120.220]   File "/usr/lib/apx-hcc/.venv/lib/python2.7/site-packages/django/template/defaulttags.py", line 284, in render<br>[Thu Aug 21 22:06:06 2014] [error] [client 72.247.120.220]     return nodelist.render(context)<br>[Thu Aug 21 22:06:06 2014] [error] [client 72.247.120.220]   File "/usr/lib/apx-hcc/.venv/lib/python2.7/site-packages/django/template/base.py", line 830, in render<br>[Thu Aug 21 22:06:06 2014] [error] [client 72.247.120.220]     bit = self.render_node(node, context)<br>[Thu Aug 21 22:06:06 2014] [error] [client 72.247.120.220]   File "/usr/lib/apx-hcc/.venv/lib/python2.7/site-packages/django/template/base.py", line 844, in render_node<br>[Thu Aug 21 22:06:06 2014] [error] [client 72.247.120.220]     return node.render(context)<br>[Thu Aug 21 22:06:06 2014] [error] [client 72.247.120.220]   File "/usr/lib/apx-hcc/.venv/lib/python2.7/site-packages/django/template/base.py", line 881, in render<br>[Thu Aug 21 22:06:06 2014] [error] [client 72.247.120.220]     output = self.filter_expression.resolve(context)<br>[Thu Aug 21 22:06:06 2014] [error] [client 72.247.120.220]   File "/usr/lib/apx-hcc/.venv/lib/python2.7/site-packages/django/template/base.py", line 578, in resolve<br>[Thu Aug 21 22:06:06 2014] [error] [client 72.247.120.220]     obj = self.var.resolve(context)<br>[Thu Aug 21 22:06:06 2014] [error] [client 72.247.120.220]   File "/usr/lib/apx-hcc/.venv/lib/python2.7/site-packages/django/template/base.py", line 728, in resolve<br>[Thu Aug 21 22:06:06 2014] [error] [client 72.247.120.220]     value = self._resolve_lookup(context)<br>[Thu Aug 21 22:06:06 2014] [error] [client 72.247.120.220]   File "/usr/lib/apx-hcc/.venv/lib/python2.7/site-packages/django/template/base.py", line 779, in _resolve_lookup<br>[Thu Aug 21 22:06:06 2014] [error] [client 72.247.120.220]     current = current()<br>[Thu Aug 21 22:06:06 2014] [error] [client 72.247.120.220]   File "/usr/lib/apx-hcc/.venv/lib/python2.7/site-packages/django/http/request.py", line 112, in build_absolute_uri<br>[Thu Aug 21 22:06:06 2014] [error] [client 72.247.120.220]     self.get_host(), self.path)<br>[Thu Aug 21 22:06:06 2014] [error] [client 72.247.120.220]   File "/usr/lib/apx-hcc/.venv/lib/python2.7/site-packages/django/http/request.py", line 72, in get_host<br>[Thu Aug 21 22:06:06 2014] [error] [client 72.247.120.220]     "Invalid HTTP_HOST header (you may need to set ALLOWED_HOSTS): %s" % host)<br>[Thu Aug 21 22:06:06 2014] [error] [client 72.247.120.220] SuspiciousOperation: Invalid HTTP_HOST header (you may need to set ALLOWED_HOSTS): all-s3-us-ic2.digitalhub.com.akadns.net<br>[Thu Aug 21 22:06:39 2014] [error] ('production.hcc', 1408683999, {'sys_module': 'base', 'source': 'django.request', 'host': '72.46.140.186', 'session': None, 'user': u'', 'time': '1408709199466', 'datestamp': '2014-08-22T05:06:39.466101', 'level': 'ERROR', 'sys_host': 'ip-10-172-93-72', 'msecs': 465.501070022583})<br>[Thu Aug 21 22:06:39 2014] [error] [client 205.185.205.132] mod_wsgi (pid=1758): Exception occurred processing WSGI script '/usr/lib/apx-hcc/hcc_project/hcc_project/wsgi.py'.<br>[Thu Aug 21 22:06:39 2014] [error] [client 205.185.205.132] Traceback (most recent call last):<br>[Thu Aug 21 22:06:39 2014] [error] [client 205.185.205.132]   File "/usr/lib/apx-hcc/.venv/lib/python2.7/site-packages/django/core/handlers/wsgi.py", line 255, in __call__<br>[Thu Aug 21 22:06:39 2014] [error] [client 205.185.205.132]     response = self.get_response(request)<br>[Thu Aug 21 22:06:39 2014] [error] [client 205.185.205.132]   File "/usr/lib/apx-hcc/.venv/lib/python2.7/site-packages/django/core/handlers/base.py", line 178, in get_response<br>[Thu Aug 21 22:06:39 2014] [error] [client 205.185.205.132]     response = self.handle_uncaught_exception(request, resolver, sys.exc_info())<br>[Thu Aug 21 22:06:39 2014] [error] [client 205.185.205.132]   File "/usr/lib/apx-hcc/.venv/lib/python2.7/site-packages/django/core/handlers/base.py", line 212, in handle_uncaught_exception<br>[Thu Aug 21 22:06:39 2014] [error] [client 205.185.205.132]     'request': request<br>[Thu Aug 21 22:06:39 2014] [error] [client 205.185.205.132]   File "/usr/lib64/python2.7/logging/__init__.py", line 1166, in error<br>[Thu Aug 21 22:06:39 2014] [error] [client 205.185.205.132]     self._log(ERROR, msg, args, **kwargs)<br>[Thu Aug 21 22:06:39 2014] [error] [client 205.185.205.132]   File "/usr/lib64/python2.7/logging/__init__.py", line 1258, in _log<br>[Thu Aug 21 22:06:39 2014] [error] [client 205.185.205.132]     self.handle(record)<br>[Thu Aug 21 22:06:39 2014] [error] [client 205.185.205.132]   File "/usr/lib64/python2.7/logging/__init__.py", line 1268, in handle<br>[Thu Aug 21 22:06:39 2014] [error] [client 205.185.205.132]     self.callHandlers(record)<br>[Thu Aug 21 22:06:39 2014] [error] [client 205.185.205.132]   File "/usr/lib64/python2.7/logging/__init__.py", line 1308, in callHandlers<br>[Thu Aug 21 22:06:39 2014] [error] [client 205.185.205.132]     hdlr.handle(record)<br>[Thu Aug 21 22:06:39 2014] [error] [client 205.185.205.132]   File "/usr/lib64/python2.7/logging/__init__.py", line 748, in handle<br>[Thu Aug 21 22:06:39 2014] [error] [client 205.185.205.132]     self.emit(record)<br>[Thu Aug 21 22:06:39 2014] [error] [client 205.185.205.132]   File "/usr/lib/apx-hcc/.venv/lib/python2.7/site-packages/django/utils/log.py", line 112, in emit<br>[Thu Aug 21 22:06:39 2014] [error] [client 205.185.205.132]     html_message = self.include_html and reporter.get_traceback_html() or None<br>[Thu Aug 21 22:06:39 2014] [error] [client 205.185.205.132]   File "/usr/lib/apx-hcc/.venv/lib/python2.7/site-packages/django/views/debug.py", line 298, in get_traceback_html<br>[Thu Aug 21 22:06:39 2014] [error] [client 205.185.205.132]     return t.render(c)<br>[Thu Aug 21 22:06:39 2014] [error] [client 205.185.205.132]   File "/usr/lib/apx-hcc/.venv/lib/python2.7/site-packages/django/template/base.py", line 140, in render<br>[Thu Aug 21 22:06:39 2014] [error] [client 205.185.205.132]     return self._render(context)<br>[Thu Aug 21 22:06:39 2014] [error] [client 205.185.205.132]   File "/usr/lib/apx-hcc/.venv/lib/python2.7/site-packages/django/template/base.py", line 134, in _render<br>[Thu Aug 21 22:06:39 2014] [error] [client 205.185.205.132]     return self.nodelist.render(context)<br>[Thu Aug 21 22:06:39 2014] [error] [client 205.185.205.132]   File "/usr/lib/apx-hcc/.venv/lib/python2.7/site-packages/django/template/base.py", line 830, in render<br>[Thu Aug 21 22:06:39 2014] [error] [client 205.185.205.132]     bit = self.render_node(node, context)<br>[Thu Aug 21 22:06:39 2014] [error] [client 205.185.205.132]   File "/usr/lib/apx-hcc/.venv/lib/python2.7/site-packages/django/template/base.py", line 844, in render_node<br>[Thu Aug 21 22:06:39 2014] [error] [client 205.185.205.132]     return node.render(context)<br>[Thu Aug 21 22:06:39 2014] [error] [client 205.185.205.132]   File "/usr/lib/apx-hcc/.venv/lib/python2.7/site-packages/django/template/defaulttags.py", line 284, in render<br>[Thu Aug 21 22:06:39 2014] [error] [client 205.185.205.132]     return nodelist.render(context)<br>[Thu Aug 21 22:06:39 2014] [error] [client 205.185.205.132]   File "/usr/lib/apx-hcc/.venv/lib/python2.7/site-packages/django/template/base.py", line 830, in render<br>[Thu Aug 21 22:06:39 2014] [error] [client 205.185.205.132]     bit = self.render_node(node, context)<br>[Thu Aug 21 22:06:39 2014] [error] [client 205.185.205.132]   File "/usr/lib/apx-hcc/.venv/lib/python2.7/site-packages/django/template/base.py", line 844, in render_node<br>[Thu Aug 21 22:06:39 2014] [error] [client 205.185.205.132]     return node.render(context)<br>[Thu Aug 21 22:06:39 2014] [error] [client 205.185.205.132]   File "/usr/lib/apx-hcc/.venv/lib/python2.7/site-packages/django/template/base.py", line 881, in render<br>[Thu Aug 21 22:06:39 2014] [error] [client 205.185.205.132]     output = self.filter_expression.resolve(context)<br>[Thu Aug 21 22:06:39 2014] [error] [client 205.185.205.132]   File "/usr/lib/apx-hcc/.venv/lib/python2.7/site-packages/django/template/base.py", line 578, in resolve<br>[Thu Aug 21 22:06:39 2014] [error] [client 205.185.205.132]     obj = self.var.resolve(context)<br>[Thu Aug 21 22:06:39 2014] [error] [client 205.185.205.132]   File "/usr/lib/apx-hcc/.venv/lib/python2.7/site-packages/django/template/base.py", line 728, in resolve<br>[Thu Aug 21 22:06:39 2014] [error] [client 205.185.205.132]     value = self._resolve_lookup(context)<br>[Thu Aug 21 22:06:39 2014] [error] [client 205.185.205.132]   File "/usr/lib/apx-hcc/.venv/lib/python2.7/site-packages/django/template/base.py", line 779, in _resolve_lookup<br>[Thu Aug 21 22:06:39 2014] [error] [client 205.185.205.132]     current = current()<br>[Thu Aug 21 22:06:39 2014] [error] [client 205.185.205.132]   File "/usr/lib/apx-hcc/.venv/lib/python2.7/site-packages/django/http/request.py", line 112, in build_absolute_uri<br>[Thu Aug 21 22:06:39 2014] [error] [client 205.185.205.132]     self.get_host(), self.path)<br>[Thu Aug 21 22:06:39 2014] [error] [client 205.185.205.132]   File "/usr/lib/apx-hcc/.venv/lib/python2.7/site-packages/django/http/request.py", line 72, in get_host<br>[Thu Aug 21 22:06:39 2014] [error] [client 205.185.205.132]     "Invalid HTTP_HOST header (you may need to set ALLOWED_HOSTS): %s" % host)<br>[Thu Aug 21 22:06:39 2014] [error] [client 205.185.205.132] SuspiciousOperation: Invalid HTTP_HOST header (you may need to set ALLOWED_HOSTS): all-s3-us-ic2.digitalhub.com.akadns.net<br>[Fri Aug 22 16:09:20 2014] [error] ('production.hcc', 1408748960, {'sys_module': 'base', 'source': 'django.request', 'host': '64.120.6.122', 'session': None, 'user': u'', 'time': '1408774160675', 'datestamp': '2014-08-22T23:09:20.675343', 'level': 'ERROR', 'sys_host': 'ip-10-172-93-72', 'msecs': 674.7100353240967})<br>[Fri Aug 22 16:09:20 2014] [error] [client 186.153.216.42] mod_wsgi (pid=1758): Exception occurred processing WSGI script '/usr/lib/apx-hcc/hcc_project/hcc_project/wsgi.py'.<br>[Fri Aug 22 16:09:20 2014] [error] [client 186.153.216.42] Traceback (most recent call last):<br>[Fri Aug 22 16:09:20 2014] [error] [client 186.153.216.42]   File "/usr/lib/apx-hcc/.venv/lib/python2.7/site-packages/django/core/handlers/wsgi.py", line 255, in __call__<br>[Fri Aug 22 16:09:20 2014] [error] [client 186.153.216.42]     response = self.get_response(request)<br>[Fri Aug 22 16:09:20 2014] [error] [client 186.153.216.42]   File "/usr/lib/apx-hcc/.venv/lib/python2.7/site-packages/django/core/handlers/base.py", line 178, in get_response<br>[Fri Aug 22 16:09:20 2014] [error] [client 186.153.216.42]     response = self.handle_uncaught_exception(request, resolver, sys.exc_info())<br>[Fri Aug 22 16:09:20 2014] [error] [client 186.153.216.42]   File "/usr/lib/apx-hcc/.venv/lib/python2.7/site-packages/django/core/handlers/base.py", line 212, in handle_uncaught_exception<br>[Fri Aug 22 16:09:20 2014] [error] [client 186.153.216.42]     'request': request<br>[Fri Aug 22 16:09:20 2014] [error] [client 186.153.216.42]   File "/usr/lib64/python2.7/logging/__init__.py", line 1166, in error<br>[Fri Aug 22 16:09:20 2014] [error] [client 186.153.216.42]     self._log(ERROR, msg, args, **kwargs)<br>[Fri Aug 22 16:09:20 2014] [error] [client 186.153.216.42]   File "/usr/lib64/python2.7/logging/__init__.py", line 1258, in _log<br>[Fri Aug 22 16:09:20 2014] [error] [client 186.153.216.42]     self.handle(record)<br>[Fri Aug 22 16:09:20 2014] [error] [client 186.153.216.42]   File "/usr/lib64/python2.7/logging/__init__.py", line 1268, in handle<br>[Fri Aug 22 16:09:20 2014] [error] [client 186.153.216.42]     self.callHandlers(record)<br>[Fri Aug 22 16:09:20 2014] [error] [client 186.153.216.42]   File "/usr/lib64/python2.7/logging/__init__.py", line 1308, in callHandlers<br>[Fri Aug 22 16:09:20 2014] [error] [client 186.153.216.42]     hdlr.handle(record)<br>[Fri Aug 22 16:09:20 2014] [error] [client 186.153.216.42]   File "/usr/lib64/python2.7/logging/__init__.py", line 748, in handle<br>[Fri Aug 22 16:09:20 2014] [error] [client 186.153.216.42]     self.emit(record)<br>[Fri Aug 22 16:09:20 2014] [error] [client 186.153.216.42]   File "/usr/lib/apx-hcc/.venv/lib/python2.7/site-packages/django/utils/log.py", line 112, in emit<br>[Fri Aug 22 16:09:20 2014] [error] [client 186.153.216.42]     html_message = self.include_html and reporter.get_traceback_html() or None<br>[Fri Aug 22 16:09:20 2014] [error] [client 186.153.216.42]   File "/usr/lib/apx-hcc/.venv/lib/python2.7/site-packages/django/views/debug.py", line 298, in get_traceback_html<br>[Fri Aug 22 16:09:20 2014] [error] [client 186.153.216.42]     return t.render(c)<br>[Fri Aug 22 16:09:20 2014] [error] [client 186.153.216.42]   File "/usr/lib/apx-hcc/.venv/lib/python2.7/site-packages/django/template/base.py", line 140, in render<br>[Fri Aug 22 16:09:20 2014] [error] [client 186.153.216.42]     return self._render(context)<br>[Fri Aug 22 16:09:20 2014] [error] [client 186.153.216.42]   File "/usr/lib/apx-hcc/.venv/lib/python2.7/site-packages/django/template/base.py", line 134, in _render<br>[Fri Aug 22 16:09:20 2014] [error] [client 186.153.216.42]     return self.nodelist.render(context)<br>[Fri Aug 22 16:09:20 2014] [error] [client 186.153.216.42]   File "/usr/lib/apx-hcc/.venv/lib/python2.7/site-packages/django/template/base.py", line 830, in render<br>[Fri Aug 22 16:09:20 2014] [error] [client 186.153.216.42]     bit = self.render_node(node, context)<br>[Fri Aug 22 16:09:20 2014] [error] [client 186.153.216.42]   File "/usr/lib/apx-hcc/.venv/lib/python2.7/site-packages/django/template/base.py", line 844, in render_node<br>[Fri Aug 22 16:09:20 2014] [error] [client 186.153.216.42]     return node.render(context)<br>[Fri Aug 22 16:09:20 2014] [error] [client 186.153.216.42]   File "/usr/lib/apx-hcc/.venv/lib/python2.7/site-packages/django/template/defaulttags.py", line 284, in render<br>[Fri Aug 22 16:09:20 2014] [error] [client 186.153.216.42]     return nodelist.render(context)<br>[Fri Aug 22 16:09:20 2014] [error] [client 186.153.216.42]   File "/usr/lib/apx-hcc/.venv/lib/python2.7/site-packages/django/template/base.py", line 830, in render<br>[Fri Aug 22 16:09:20 2014] [error] [client 186.153.216.42]     bit = self.render_node(node, context)<br>[Fri Aug 22 16:09:20 2014] [error] [client 186.153.216.42]   File "/usr/lib/apx-hcc/.venv/lib/python2.7/site-packages/django/template/base.py", line 844, in render_node<br>[Fri Aug 22 16:09:20 2014] [error] [client 186.153.216.42]     return node.render(context)<br>[Fri Aug 22 16:09:20 2014] [error] [client 186.153.216.42]   File "/usr/lib/apx-hcc/.venv/lib/python2.7/site-packages/django/template/base.py", line 881, in render<br>[Fri Aug 22 16:09:20 2014] [error] [client 186.153.216.42]     output = self.filter_expression.resolve(context)<br>[Fri Aug 22 16:09:20 2014] [error] [client 186.153.216.42]   File "/usr/lib/apx-hcc/.venv/lib/python2.7/site-packages/django/template/base.py", line 578, in resolve<br>[Fri Aug 22 16:09:20 2014] [error] [client 186.153.216.42]     obj = self.var.resolve(context)<br>[Fri Aug 22 16:09:20 2014] [error] [client 186.153.216.42]   File "/usr/lib/apx-hcc/.venv/lib/python2.7/site-packages/django/template/base.py", line 728, in resolve<br>[Fri Aug 22 16:09:20 2014] [error] [client 186.153.216.42]     value = self._resolve_lookup(context)<br>[Fri Aug 22 16:09:20 2014] [error] [client 186.153.216.42]   File "/usr/lib/apx-hcc/.venv/lib/python2.7/site-packages/django/template/base.py", line 779, in _resolve_lookup<br>[Fri Aug 22 16:09:20 2014] [error] [client 186.153.216.42]     current = current()<br>[Fri Aug 22 16:09:20 2014] [error] [client 186.153.216.42]   File "/usr/lib/apx-hcc/.venv/lib/python2.7/site-packages/django/http/request.py", line 112, in build_absolute_uri<br>[Fri Aug 22 16:09:20 2014] [error] [client 186.153.216.42]     self.get_host(), self.path)<br>[Fri Aug 22 16:09:20 2014] [error] [client 186.153.216.42]   File "/usr/lib/apx-hcc/.venv/lib/python2.7/site-packages/django/http/request.py", line 72, in get_host<br>[Fri Aug 22 16:09:20 2014] [error] [client 186.153.216.42]     "Invalid HTTP_HOST header (you may need to set ALLOWED_HOSTS): %s" % host)<br>[Fri Aug 22 16:09:20 2014] [error] [client 186.153.216.42] SuspiciousOperation: Invalid HTTP_HOST header (you may need to set ALLOWED_HOSTS): 50.18.90.145<br></body></html>